Workbook

Sheet SPEC
A1: CALCULATION SPECIFICATION — Arrow Shaft Spine & Weight Grouping
A2: Reference document for reimplementing this analysis as a web application. Mirrors the live formulas on the ANALYSIS, GROUPS and CLUSTERS tabs. Parameter values in column D are linked, so they always show what the workbook is currently using.
A4: 1. INPUTS
A5: Parameter | B5: Symbol | C5: Source cell | D5: Current | E5: Description
A6: Spine spec floor (lb) | B6: specMin | C6: ANALYSIS!B5 | D6: =ANALYSIS!$B$5 -> 54 | E6: Lower edge of the advertised spine range. Drives the in-spec flags only — it has no effect on grouping.
A7: Spine spec ceiling (lb) | B7: specMax | C7: ANALYSIS!B6 | D7: =ANALYSIS!$B$6 -> 60 | E7: Upper edge of the advertised spine range.
A8: Max A/B spine difference (lb) | B8: abTol | C8: ANALYSIS!B7 | D8: =ANALYSIS!$B$7 -> 1 | E8: A shaft whose two spine readings differ by more than this is flagged inconsistent — a quality signal, not a grouping input.
A9: Max spine spread in a group (lb) | B9: spineTol | C9: ANALYSIS!G5 | D9: =ANALYSIS!$G$5 -> 3 | E9: Grouping tolerance. Any two members of a group must be within this on average spine.
A10: Max weight spread in a group (g) | B10: weightTol | C10: ANALYSIS!G6 | D10: =ANALYSIS!$G$6 -> 0.5 | E10: Grouping tolerance. Any two members of a group must be within this on weight.
A11: Usable group threshold | B11: minGroupSize | C11: ANALYSIS!G7 | D11: =ANALYSIS!$G$7 -> 3 | E11: Minimum members before a group counts as usable in the summary tallies. Reporting only — the algorithms impose no size cap.
A13: Raw per-shaft record | E13: batch, shaftId, spineA, spineB, weight — five fields, one row per shaft. Source data: 100 shafts across batches 19 and 20.
A15: 2. PER-SHAFT DERIVED FIELDS
A16: Field | E16: Definition
A17: avgSpine | E17: (spineA + spineB) / 2
A18: abSpread | E18: abs(spineA - spineB)
A19: inSpec | E19: specMin <= avgSpine <= specMax
A20: abConsistent | E20: abSpread <= abTol
A22: 3. QC STATISTICS
A23: Computed per batch and combined | E23: Count; min / max / mean / median / sample standard deviation of avgSpine; mean and max abSpread; count where abSpread > abTol; count inSpec; percent inSpec (= inSpec count / total); count where avgSpine < specMin; count where avgSpine > specMax.
A24: Weight statistics | E24: Count; min / max / mean / median / sample standard deviation of weight; range (= max - min).
A25: Current output | E25: 75 of 100 shafts in spec (54–60 lb); 25 below floor; 0 above ceiling; mean spine 55.22 lb; weight 21.18–26.76 g; one shaft (20-50) fails the A/B consistency check at 2.0 lb.
A27: 4. DISTRIBUTION HISTOGRAM
A28: Binning rule | E28: Fixed 1 lb bins starting at floor(min(avgSpine)). A shaft falls in bin b when b <= avgSpine < b + 1. Counted separately per batch. Independent of spineTol — this is a display aid, not part of grouping.
A30: 5. GROUPING METHOD A — FIXED GRID
A31: Implemented on | E31: GROUPS tab. Fast, deterministic overview — but see the caveat below. Do not ship this as the primary algorithm.
A32: Band assignment | E32: spineBand = floor(avgSpine / spineTol) * spineTol weightBand = floor(weight / weightTol) * weightTol groupKey = (spineBand, weightBand)
A33: Group definition | E33: A group is every shaft sharing a groupKey. Because all members sit inside one half-open band of width spineTol × weightTol, the in-group spread is guaranteed below tolerance. No size cap.
A34: Ordering | E34: Sort groups by member count descending, then by groupKey ascending as a stable tie-break.
A35: Cross-tab | E35: Count of shafts by spineBand (rows) × weightBand (columns). Row and column totals must reconcile to the shaft count.
A36: ⚠ Known flaw | E36: Band edges are arbitrary. Two shafts 0.2 g apart land in different groups if a boundary falls between them, so the method systematically under-reports the best groups. Observed case: shafts 19-28 (23.49 g), 19-35 (23.47 g) and 19-43 (23.38 g) were split away from a group whose lightest member was 23.71 g — all three are within the 0.5 g tolerance of it. The grid reported 10 shafts where the true cluster held 13–14.
A38: 6. GROUPING METHOD B — SLIDING-WINDOW GREEDY CLUSTERING
A39: Implemented on | E39: CLUSTERS tab. This is the method to build on. No fixed bands — windows slide to the data.
A40: Algorithm | E40: unassigned = all shafts clusters = [] repeat until unassigned is empty (or a round cap is reached): best = null for each shaft i in unassigned: window_i = { j in unassigned : spine_i <= avgSpine_j <= spine_i + spineTol AND weight_i <= weight_j <= weight_i + weightTol } if size(window_i) > size(best): best = window_i # ties resolve to lowest shaftId clusters.append(best) unassigned = unassigned - best
A41: Correctness guarantee | E41: Every member lies inside [anchor, anchor + tol] on both axes, so spineSpread <= spineTol and weightSpread <= weightTol hold by construction. Verified on all 15 clusters produced by the workbook.
A42: Per-cluster outputs | E42: size, minSpine, maxSpine, spineSpread, minWeight, maxWeight, weightSpread, member list, and allInSpec = (minSpine >= specMin AND maxSpine <= specMax).
A43: Spreadsheet round cap | E43: The workbook runs a fixed 15 rounds because formulas cannot loop; that placed 85 of 100 shafts, leaving 15 as 1–2 shaft remnants. In code, run to exhaustion instead — there is no reason to cap it.
A44: Current output | E44: 15 clusters. Largest holds 14 shafts (spine 55.0–57.5 lb, weight 23.85–24.35 g, fully in spec). 12 clusters have 3+ members covering 79 shafts; 7 of those are fully in spec covering 43 shafts.
A46: 7. TWO HEURISTICS TO FIX IN CODE
A47: Why they exist | E47: The spreadsheet tolerates both compromises because cell formulas cannot iterate or backtrack. A web application has no such excuse — fix both.
A48: (a) Anchoring is approximate | E48: Each candidate window is anchored at a single shaft — that shaft's spine becomes the window's spine floor AND its weight becomes the weight floor. The true optimum may need the spine floor from shaft a and the weight floor from a different shaft b, so the current search can miss the largest window.
...

Sheet BATCH19
A1: BATCH 19 55-60#
A2: Shaft# | B2: Spine A (lb) | C2: Spine B (lb) | D2: Weight (g)
A3: 19-01 | B3: 56 | C3: 55 | D3: 23.23
A4: 19-02 | B4: 58 | C4: 58 | D4: 24.7
A5: 19-03 | B5: 52 | C5: 52 | D5: 22.19
A6: 19-04 | B6: 55 | C6: 55 | D6: 24.03
A7: 19-05 | B7: 56 | C7: 56 | D7: 21.93
A8: 19-06 | B8: 55 | C8: 55 | D8: 23.85
A9: 19-07 | B9: 52 | C9: 52 | D9: 21.59
A10: 19-08 | B10: 53 | C10: 53 | D10: 21.54
A11: 19-09 | B11: 50 | C11: 50 | D11: 22.67
A12: 19-10 | B12: 56 | C12: 56 | D12: 24.67
A13: 19-11 | B13: 52 | C13: 52 | D13: 23.14
A14: 19-12 | B14: 58 | C14: 57 | D14: 24.3
... A52: 19-50 | B52: 56 | C52: 56 | D52: 25.15

Sheet BATCH20
A1: BATCH 20 55-60#
A2: Shaft# | B2: Spine A (lb) | C2: Spine B (lb) | D2: Weight (g)
A3: 20-01 | B3: 56 | C3: 55 | D3: 22.76
A4: 20-02 | B4: 53 | C4: 53 | D4: 23.03
A5: 20-03 | B5: 55 | C5: 55 | D5: 23.97
A6: 20-04 | B6: 58 | C6: 58 | D6: 23.56
A7: 20-05 | B7: 56 | C7: 56 | D7: 22.26
A8: 20-06 | B8: 56 | C8: 56 | D8: 22.35
A9: 20-07 | B9: 56 | C9: 56 | D9: 23.35
A10: 20-08 | B10: 57 | C10: 57 | D10: 23.73
A11: 20-09 | B11: 56 | C11: 56 | D11: 25.21
A12: 20-10 | B12: 56 | C12: 56 | D12: 24.35
A13: 20-11 | B13: 55 | C13: 55 | D13: 24.56
A14: 20-12 | B14: 55 | C14: 55 | D14: 22.45
... A18: 20-16 | B18: 55 | C18: 55 | D18: 23.71
A19: 20-17 | B19: 53 | C19: 53 | D19: 22.75 | G19: ~
A20: 20-18 | B20: 56 | C20: 56 | D20: 25.13
A21: 20-19 | B21: 58 | C21: 58 | D21: 21.8
A22: 20-20 | B22: 53 | C22: 52 | D22: 22.31
A23: 20-21 | B23: 55 | C23: 55 | D23: 23.94
A24: 20-22 | B24: 56 | C24: 56 | D24: 22.44
A25: 20-23 | B25: 55 | C25: 55 | D25: 23.82
A26: 20-24 | B26: 59 | C26: 58 | D26: 24.48
A27: 20-25 | B27: 56 | C27: 56 | D27: 24.35
A28: 20-26 | B28: 55 | C28: 55 | D28: 23.1
A29: 20-27 | B29: 56 | C29: 55 | D29: 21.5
A30: 20-28 | B30: 55 | C30: 55 | D30: 24.34
A31: 20-29 | B31: 55 | C31: 55 | D31: 25.35
... A52: 20-50 | B52: 58 | C52: 56 | D52: 24.41

Sheet CLUSTERS
A1: ="True Clusters — sliding window, "&$B$3&" lb spine / "&$B$4&" g weight" -> True Clusters — sliding window, 3 lb spine / 0.5 g weight
A2: Method: no fixed bands. Every shaft is tested as the corner of a window (spine lo → lo+tol, weight lo → lo+tol). The window holding the most shafts becomes Cluster 1; those shafts are removed and the search repeats. Clusters are therefore disjoint and found largest-first, so near-boundary shafts are no longer split off.
A3: Spine tolerance (lb) | B3: =ANALYSIS!$G$5 -> 3 | D3: Clusters with 3+ shafts | E3: =COUNTIF($B$8:$B$22,">="&ANALYSIS!$G$7) -> 12 | F3: Largest cluster | G3: =MAX($B$8:$B$22) -> 14 | H3: In-spec clusters (3+ shafts) | I3: =COUNTIFS($B$8:$B$22,">="&ANALYSIS!$G$7,$I$8:$I$22,"Yes") -> 7
A4: Weight tolerance (g) | B4: =ANALYSIS!$G$6 -> 0.5 | D4: Shafts in those clusters | E4: =SUMIF($B$8:$B$22,">="&ANALYSIS!$G$7,$B$8:$B$22) -> 79 | F4: Shafts left over (after 15 rounds) | G4: =COUNTA($A$25:$A$124)-SUM($B$8:$B$22) -> 15 | H4: Shafts in in-spec clusters | I4: =SUMIFS($B$8:$B$22,$B$8:$B$22,">="&ANALYSIS!$G$7,$I$8:$I$22,"Yes") -> 43
A6: CLUSTER SUMMARY — disjoint, largest first
A7: Cluster # | B7: Shafts | C7: Min spine | D7: Max spine | E7: Spine spread | F7: Min wt | G7: Max wt | H7: Wt spread | I7: All in spec? | J7: Members
A8: 1 | B8: =COUNTIF($D$25:$D$124,$A8) -> 14 | C8: =_xlfn.MINIFS($B$25:$B$124,$D$25:$D$124,$A8) -> 55 | D8: =_xlfn.MAXIFS($B$25:$B$124,$D$25:$D$124,$A8) -> 57.5 | E8: =D8-C8 -> 2.5 | F8: =_xlfn.MINIFS($C$25:$C$124,$D$25:$D$124,$A8) -> 23.85 | G8: =_xlfn.MAXIFS($C$25:$C$124,$D$25:$D$124,$A8) -> 24.35 | H8: =G8-F8 -> 0.5 | I8: =IF(AND(C8>=ANALYSIS!$B$5,D8<=ANALYSIS!$B$6),"Yes","No") -> Yes | J8: {=_xlfn.TEXTJOIN(", ",TRUE,IF($D$25:$D$124=$A8,$A$25:$A$124,""))} -> 19-04, 19-06, 19-12, 19-25, 19-45, 19-46, 20-03, 20-10, 20-21, 20-25, 20-28, 20-35, 20-44, 20-45
A9: =A8+1 -> 2 | B9: =COUNTIF($D$25:$D$124,$A9) -> 11 | C9: =_xlfn.MINIFS($B$25:$B$124,$D$25:$D$124,$A9) -> 53 | D9: =_xlfn.MAXIFS($B$25:$B$124,$D$25:$D$124,$A9) -> 56 | E9: =D9-C9 -> 3 | F9: =_xlfn.MINIFS($C$25:$C$124,$D$25:$D$124,$A9) -> 23.03 | G9: =_xlfn.MAXIFS($C$25:$C$124,$D$25:$D$124,$A9) -> 23.49 | H9: =G9-F9 -> 0.46 | I9: =IF(AND(C9>=ANALYSIS!$B$5,D9<=ANALYSIS!$B$6),"Yes","No") -> No | J9: {=_xlfn.TEXTJOIN(", ",TRUE,IF($D$25:$D$124=$A9,$A$25:$A$124,""))} -> 19-01, 19-14, 19-15, 19-22, 19-28, 19-35, 19-43, 20-02, 20-07, 20-14, 20-26
A10: =A9+1 -> 3 | B10: =COUNTIF($D$25:$D$124,$A10) -> 9 | C10: =_xlfn.MINIFS($B$25:$B$124,$D$25:$D$124,$A10) -> 55 | D10: =_xlfn.MAXIFS($B$25:$B$124,$D$25:$D$124,$A10) -> 57.5 | E10: =D10-C10 -> 2.5 | F10: =_xlfn.MINIFS($C$25:$C$124,$D$25:$D$124,$A10) -> 25.09 | G10: =_xlfn.MAXIFS($C$25:$C$124,$D$25:$D$124,$A10) -> 25.52 | H10: =G10-F10 -> 0.43 | I10: =IF(AND(C10>=ANALYSIS!$B$5,D10<=ANALYSIS!$B$6),"Yes","No") -> Yes | J10: {=_xlfn.TEXTJOIN(", ",TRUE,IF($D$25:$D$124=$A10,$A$25:$A$124,""))} -> 19-17, 19-23, 19-31, 19-50, 20-09, 20-13, 20-18, 20-29, 20-48
A11: =A10+1 -> 4 | B11: =COUNTIF($D$25:$D$124,$A11) -> 8 | C11: =_xlfn.MINIFS($B$25:$B$124,$D$25:$D$124,$A11) -> 53 | D11: =_xlfn.MAXIFS($B$25:$B$124,$D$25:$D$124,$A11) -> 56 | E11: =D11-C11 -> 3 | F11: =_xlfn.MINIFS($C$25:$C$124,$D$25:$D$124,$A11) -> 21.49 | G11: =_xlfn.MAXIFS($C$25:$C$124,$D$25:$D$124,$A11) -> 21.93 | H11: =G11-F11 -> 0.44 | I11: =IF(AND(C11>=ANALYSIS!$B$5,D11<=ANALYSIS!$B$6),"Yes","No") -> No | J11: {=_xlfn.TEXTJOIN(", ",TRUE,IF($D$25:$D$124=$A11,$A$25:$A$124,""))} -> 19-05, 19-08, 19-13, 19-16, 19-19, 19-44, 20-27, 20-47
A12: =A11+1 -> 5 | B12: =COUNTIF($D$25:$D$124,$A12) -> 7 | C12: =_xlfn.MINIFS($B$25:$B$124,$D$25:$D$124,$A12) -> 53 | D12: =_xlfn.MAXIFS($B$25:$B$124,$D$25:$D$124,$A12) -> 56 | E12: =D12-C12 -> 3 | F12: =_xlfn.MINIFS($C$25:$C$124,$D$25:$D$124,$A12) -> 22.06 | G12: =_xlfn.MAXIFS($C$25:$C$124,$D$25:$D$124,$A12) -> 22.5 | H12: =G12-F12 -> 0.44 | I12: =IF(AND(C12>=ANALYSIS!$B$5,D12<=ANALYSIS!$B$6),"Yes","No") -> No | J12: {=_xlfn.TEXTJOIN(", ",TRUE,IF($D$25:$D$124=$A12,$A$25:$A$124,""))} -> 19-34, 19-41, 20-05, 20-06, 20-12, 20-22, 20-31
A13: =A12+1 -> 6 | B13: =COUNTIF($D$25:$D$124,$A13) -> 6 | C13: =_xlfn.MINIFS($B$25:$B$124,$D$25:$D$124,$A13) -> 52 | D13: =_xlfn.MAXIFS($B$25:$B$124,$D$25:$D$124,$A13) -> 55 | E13: =D13-C13 -> 3 | F13: =_xlfn.MINIFS($C$25:$C$124,$D$25:$D$124,$A13) -> 23.46 | G13: =_xlfn.MAXIFS($C$25:$C$124,$D$25:$D$124,$A13) -> 23.82 | H13: =G13-F13 -> 0.36 | I13: =IF(AND(C13>=ANALYSIS!$B$5,D13<=ANALYSIS!$B$6),"Yes","No") -> No | J13: {=_xlfn.TEXTJOIN(", ",TRUE,IF($D$25:$D$124=$A13,$A$25:$A$124,""))} -> 19-38, 19-40, 20-16, 20-23, 20-33, 20-42
A14: =A13+1 -> 7 | B14: =COUNTIF($D$25:$D$124,$A14) -> 6 | C14: =_xlfn.MINIFS($B$25:$B$124,$D$25:$D$124,$A14) -> 55 | D14: =_xlfn.MAXIFS($B$25:$B$124,$D$25:$D$124,$A14) -> 58 | E14: =D14-C14 -> 3 | F14: =_xlfn.MINIFS($C$25:$C$124,$D$25:$D$124,$A14) -> 22.62 | G14: =_xlfn.MAXIFS($C$25:$C$124,$D$25:$D$124,$A14) -> 23 | H14: =G14-F14 -> 0.38 | I14: =IF(AND(C14>=ANALYSIS!$B$5,D14<=ANALYSIS!$B$6),"Yes","No") -> Yes | J14: {=_xlfn.TEXTJOIN(", ",TRUE,IF($D$25:$D$124=$A14,$A$25:$A$124,""))} -> 19-20, 19-32, 20-01, 20-30, 20-36, 20-38
A15: =A14+1 -> 8 | B15: =COUNTIF($D$25:$D$124,$A15) -> 4 | C15: =_xlfn.MINIFS($B$25:$B$124,$D$25:$D$124,$A15) -> 50 | D15: =_xlfn.MAXIFS($B$25:$B$124,$D$25:$D$124,$A15) -> 53 | E15: =D15-C15 -> 3 | F15: =_xlfn.MINIFS($C$25:$C$124,$D$25:$D$124,$A15) -> 22.67 | G15: =_xlfn.MAXIFS($C$25:$C$124,$D$25:$D$124,$A15) -> 23.14 | H15: =G15-F15 -> 0.47 | I15: =IF(AND(C15>=ANALYSIS!$B$5,D15<=ANALYSIS!$B$6),"Yes","No") -> No | J15: {=_xlfn.TEXTJOIN(", ",TRUE,IF($D$25:$D$124=$A15,$A$25:$A$124,""))} -> 19-09, 19-11, 19-48, 20-17
A16: =A15+1 -> 9 | B16: =COUNTIF($D$25:$D$124,$A16) -> 4 | C16: =_xlfn.MINIFS($B$25:$B$124,$D$25:$D$124,$A16) -> 57 | D16: =_xlfn.MAXIFS($B$25:$B$124,$D$25:$D$124,$A16) -> 58 | E16: =D16-C16 -> 1 | F16: =_xlfn.MINIFS($C$25:$C$124,$D$25:$D$124,$A16) -> 23.44 | G16: =_xlfn.MAXIFS($C$25:$C$124,$D$25:$D$124,$A16) -> 23.73 | H16: =G16-F16 -> 0.29 | I16: =IF(AND(C16>=ANALYSIS!$B$5,D16<=ANALYSIS!$B$6),"Yes","No") -> Yes | J16: {=_xlfn.TEXTJOIN(", ",TRUE,IF($D$25:$D$124=$A16,$A$25:$A$124,""))} -> 19-36, 20-04, 20-08, 20-15
A17: =A16+1 -> 10 | B17: =COUNTIF($D$25:$D$124,$A17) -> 4 | C17: =_xlfn.MINIFS($B$25:$B$124,$D$25:$D$124,$A17) -> 55 | D17: =_xlfn.MAXIFS($B$25:$B$124,$D$25:$D$124,$A17) -> 58 | E17: =D17-C17 -> 3 | F17: =_xlfn.MINIFS($C$25:$C$124,$D$25:$D$124,$A17) -> 24.56 | G17: =_xlfn.MAXIFS($C$25:$C$124,$D$25:$D$124,$A17) -> 24.94 | H17: =G17-F17 -> 0.38 | I17: =IF(AND(C17>=ANALYSIS!$B$5,D17<=ANALYSIS!$B$6),"Yes","No") -> Yes | J17: {=_xlfn.TEXTJOIN(", ",TRUE,IF($D$25:$D$124=$A17,$A$25:$A$124,""))} -> 19-02, 19-10, 19-47, 20-11
A18: =A17+1 -> 11 | B18: =COUNTIF($D$25:$D$124,$A18) -> 3 | C18: =_xlfn.MINIFS($B$25:$B$124,$D$25:$D$124,$A18) -> 56 | D18: =_xlfn.MAXIFS($B$25:$B$124,$D$25:$D$124,$A18) -> 59 | E18: =D18-C18 -> 3 | F18: =_xlfn.MINIFS($C$25:$C$124,$D$25:$D$124,$A18) -> 25.62 | G18: =_xlfn.MAXIFS($C$25:$C$124,$D$25:$D$124,$A18) -> 26.09 | H18: =G18-F18 -> 0.47 | I18: =IF(AND(C18>=ANALYSIS!$B$5,D18<=ANALYSIS!$B$6),"Yes","No") -> Yes | J18: {=_xlfn.TEXTJOIN(", ",TRUE,IF($D$25:$D$124=$A18,$A$25:$A$124,""))} -> 19-21, 19-27, 20-41
A19: =A18+1 -> 12 | B19: =COUNTIF($D$25:$D$124,$A19) -> 3 | C19: =_xlfn.MINIFS($B$25:$B$124,$D$25:$D$124,$A19) -> 57 | D19: =_xlfn.MAXIFS($B$25:$B$124,$D$25:$D$124,$A19) -> 58.5 | E19: =D19-C19 -> 1.5 | F19: =_xlfn.MINIFS($C$25:$C$124,$D$25:$D$124,$A19) -> 24.41 | G19: =_xlfn.MAXIFS($C$25:$C$124,$D$25:$D$124,$A19) -> 24.48 | H19: =G19-F19 -> 0.07 | I19: =IF(AND(C19>=ANALYSIS!$B$5,D19<=ANALYSIS!$B$6),"Yes","No") -> Yes | J19: {=_xlfn.TEXTJOIN(", ",TRUE,IF($D$25:$D$124=$A19,$A$25:$A$124,""))} -> 20-24, 20-46, 20-50
A20: =A19+1 -> 13 | B20: =COUNTIF($D$25:$D$124,$A20) -> 2 | C20: =_xlfn.MINIFS($B$25:$B$124,$D$25:$D$124,$A20) -> 52 | D20: =_xlfn.MAXIFS($B$25:$B$124,$D$25:$D$124,$A20) -> 52.5 | E20: =D20-C20 -> 0.5 | F20: =_xlfn.MINIFS($C$25:$C$124,$D$25:$D$124,$A20) -> 22.19 | G20: =_xlfn.MAXIFS($C$25:$C$124,$D$25:$D$124,$A20) -> 22.31 | H20: =G20-F20 -> 0.12 | I20: =IF(AND(C20>=ANALYSIS!$B$5,D20<=ANALYSIS!$B$6),"Yes","No") -> No | J20: {=_xlfn.TEXTJOIN(", ",TRUE,IF($D$25:$D$124=$A20,$A$25:$A$124,""))} -> 19-03, 20-20 | Q20: Round → | R20: =1 -> 1 | S20: =1 -> 1 | T20: =1 -> 1 | U20: =1 -> 1 | V20: =1 -> 1 | W20: =1 -> 1 | X20: =1 -> 1 | Y20: =1 -> 1 | ... AF20: =1 -> 1 | AX20: Cumulative assigned →
A21: =A20+1 -> 14 | B21: =COUNTIF($D$25:$D$124,$A21) -> 2 | C21: =_xlfn.MINIFS($B$25:$B$124,$D$25:$D$124,$A21) -> 52 | D21: =_xlfn.MAXIFS($B$25:$B$124,$D$25:$D$124,$A21) -> 52 | E21: =D21-C21 -> 0 | F21: =_xlfn.MINIFS($C$25:$C$124,$D$25:$D$124,$A21) -> 21.59 | G21: =_xlfn.MAXIFS($C$25:$C$124,$D$25:$D$124,$A21) -> 21.66 | H21: =G21-F21 -> 0.07 | I21: =IF(AND(C21>=ANALYSIS!$B$5,D21<=ANALYSIS!$B$6),"Yes","No") -> No | J21: {=_xlfn.TEXTJOIN(", ",TRUE,IF($D$25:$D$124=$A21,$A$25:$A$124,""))} -> 19-07, 19-18 | Q21: Cluster size | R21: =MAX(R$25:R$124) -> 14 | S21: =MAX(S$25:S$124) -> 11 | T21: =MAX(T$25:T$124) -> 9 | U21: =MAX(U$25:U$124) -> 8 | V21: =MAX(V$25:V$124) -> 7 | W21: =MAX(W$25:W$124) -> 6 | X21: =MAX(X$25:X$124) -> 6 | Y21: =MAX(Y$25:Y$124) -> 4 | ... AF21: =MAX(AF$25:AF$124) -> 2
A22: =A21+1 -> 15 | B22: =COUNTIF($D$25:$D$124,$A22) -> 2 | C22: =_xlfn.MINIFS($B$25:$B$124,$D$25:$D$124,$A22) -> 58 | D22: =_xlfn.MAXIFS($B$25:$B$124,$D$25:$D$124,$A22) -> 59 | E22: =D22-C22 -> 1 | F22: =_xlfn.MINIFS($C$25:$C$124,$D$25:$D$124,$A22) -> 23.24 | G22: =_xlfn.MAXIFS($C$25:$C$124,$D$25:$D$124,$A22) -> 23.29 | H22: =G22-F22 -> 0.05 | I22: =IF(AND(C22>=ANALYSIS!$B$5,D22<=ANALYSIS!$B$6),"Yes","No") -> Yes | J22: {=_xlfn.TEXTJOIN(", ",TRUE,IF($D$25:$D$124=$A22,$A$25:$A$124,""))} -> 19-24, 19-33 | Q22: Anchor spine (lb) | R22: =INDEX($B$25:$B$124,MATCH(R21,R$25:R$124,0)) -> 55 | S22: =INDEX($B$25:$B$124,MATCH(S21,S$25:S$124,0)) -> 53 | T22: =INDEX($B$25:$B$124,MATCH(T21,T$25:T$124,0)) -> 55 | U22: =INDEX($B$25:$B$124,MATCH(U21,U$25:U$124,0)) -> 53 | V22: =INDEX($B$25:$B$124,MATCH(V21,V$25:V$124,0)) -> 53 | W22: =INDEX($B$25:$B$124,MATCH(W21,W$25:W$124,0)) -> 52 | X22: =INDEX($B$25:$B$124,MATCH(X21,X$25:X$124,0)) -> 55 | Y22: =INDEX($B$25:$B$124,MATCH(Y21,Y$25:Y$124,0)) -> 50 | ... AF22: =INDEX($B$25:$B$124,MATCH(AF21,AF$25:AF$124,0)) -> 58
A23: WORKING BLOCK — 100 shafts (columns R onward are the round-by-round search) | Q23: Anchor weight (g) | R23: =INDEX($C$25:$C$124,MATCH(R21,R$25:R$124,0)) -> 23.85 | S23: =INDEX($C$25:$C$124,MATCH(S21,S$25:S$124,0)) -> 23.03 | T23: =INDEX($C$25:$C$124,MATCH(T21,T$25:T$124,0)) -> 25.09 | U23: =INDEX($C$25:$C$124,MATCH(U21,U$25:U$124,0)) -> 21.49 | V23: =INDEX($C$25:$C$124,MATCH(V21,V$25:V$124,0)) -> 22.06 | W23: =INDEX($C$25:$C$124,MATCH(W21,W$25:W$124,0)) -> 23.46 | X23: =INDEX($C$25:$C$124,MATCH(X21,X$25:X$124,0)) -> 22.62 | Y23: =INDEX($C$25:$C$124,MATCH(Y21,Y$25:Y$124,0)) -> 22.67 | ... AF23: =INDEX($C$25:$C$124,MATCH(AF21,AF$25:AF$124,0)) -> 23.24
A24: Shaft # | B24: Avg spine (lb) | C24: Weight (g) | D24: Cluster # | Q24: Window count ↓ | AG24: Assigned flag ↓ | AX24: cum0
A25: =ANALYSIS!B31 -> 19-01 | B25: =ANALYSIS!E31 -> 55.5 | C25: =ANALYSIS!G31 -> 23.23 | D25: =IFERROR(MATCH(1,$AH25:$AV25,0),"") -> 2 | R25: {=IF(AX25>0,0,SUMPRODUCT((AX$25:AX$124=0)*($B$25:$B$124>=$B25)*($B$25:$B$124<=$B25+ANALYSIS!$G$5)*($C$25:$C$124>=$C25)*($C$25:$C$124<=$C25+ANALYSIS!$G$6)))} -> 10 | S25: {=IF(AY25>0,0,SUMPRODUCT((AY$25:AY$124=0)*($B$25:$B$124>=$B25)*($B$25:$B$124<=$B25+ANALYSIS!$G$5)*($C$25:$C$124>=$C25)*($C$25:$C$124<=$C25+ANALYSIS!$G$6)))} -> 10 | T25: {=IF(AZ25>0,0,SUMPRODUCT((AZ$25:AZ$124=0)*($B$25:$B$124>=$B25)*($B$25:$B$124<=$B25+ANALYSIS!$G$5)*($C$25:$C$124>=$C25)*($C$25:$C$124<=$C25+ANALYSIS!$G$6)))} -> 0 | U25: {=IF(BA25>0,0,SUMPRODUCT((BA$25:BA$124=0)*($B$25:$B$124>=$B25)*($B$25:$B$124<=$B25+ANALYSIS!$G$5)*($C$25:$C$124>=$C25)*($C$25:$C$124<=$C25+ANALYSIS!$G$6)))} -> 0 | V25: {=IF(BB25>0,0,SUMPRODUCT((BB$25:BB$124=0)*($B$25:$B$124>=$B25)*($B$25:$B$124<=$B25+ANALYSIS!$G$5)*($C$25:$C$124>=$C25)*($C$25:$C$124<=$C25+ANALYSIS!$G$6)))} -> 0 | W25: {=IF(BC25>0,0,SUMPRODUCT((BC$25:BC$124=0)*($B$25:$B$124>=$B25)*($B$25:$B$124<=$B25+ANALYSIS!$G$5)*($C$25:$C$124>=$C25)*($C$25:$C$124<=$C25+ANALYSIS!$G$6)))} -> 0 | X25: {=IF(BD25>0,0,SUMPRODUCT((BD$25:BD$124=0)*($B$25:$B$124>=$B25)*($B$25:$B$124<=$B25+ANALYSIS!$G$5)*($C$25:$C$124>=$C25)*($C$25:$C$124<=$C25+ANALYSIS!$G$6)))} -> 0 | Y25: {=IF(BE25>0,0,SUMPRODUCT((BE$25:BE$124=0)*($B$25:$B$124>=$B25)*($B$25:$B$124<=$B25+ANALYSIS!$G$5)*($C$25:$C$124>=$C25)*($C$25:$C$124<=$C25+ANALYSIS!$G$6)))} -> 0 | ... AF25: {=IF(BL25>0,0,SUMPRODUCT((BL$25:BL$124=0)*($B$25:$B$124>=$B25)*($B$25:$B$124<=$B25+ANALYSIS!$G$5)*($C$25:$C$124>=$C25)*($C$25:$C$124<=$C25+ANALYSIS!$G$6)))} -> 0 | AH25: =IF(AND(AX25=0,$B25>=R$22,$B25<=R$22+ANALYSIS!$G$5,$C25>=R$23,$C25<=R$23+ANALYSIS!$G$6),1,0) -> 0 | AI25: =IF(AND(AY25=0,$B25>=S$22,$B25<=S$22+ANALYSIS!$G$5,$C25>=S$23,$C25<=S$23+ANALYSIS!$G$6),1,0) -> 1 | AJ25: =IF(AND(AZ25=0,$B25>=T$22,$B25<=T$22+ANALYSIS!$G$5,$C25>=T$23,$C25<=T$23+ANALYSIS!$G$6),1,0) -> 0 | AK25: =IF(AND(BA25=0,$B25>=U$22,$B25<=U$22+ANALYSIS!$G$5,$C25>=U$23,$C25<=U$23+ANALYSIS!$G$6),1,0) -> 0 | AL25: =IF(AND(BB25=0,$B25>=V$22,$B25<=V$22+ANALYSIS!$G$5,$C25>=V$23,$C25<=V$23+ANALYSIS!$G$6),1,0) -> 0 | AM25: =IF(AND(BC25=0,$B25>=W$22,$B25<=W$22+ANALYSIS!$G$5,$C25>=W$23,$C25<=W$23+ANALYSIS!$G$6),1,0) -> 0 | AN25: =IF(AND(BD25=0,$B25>=X$22,$B25<=X$22+ANALYSIS!$G$5,$C25>=X$23,$C25<=X$23+ANALYSIS!$G$6),1,0) -> 0 | AO25: =IF(AND(BE25=0,$B25>=Y$22,$B25<=Y$22+ANALYSIS!$G$5,$C25>=Y$23,$C25<=Y$23+ANALYSIS!$G$6),1,0) -> 0 | ... AV25: =IF(AND(BL25=0,$B25>=AF$22,$B25<=AF$22+ANALYSIS!$G$5,$C25>=AF$23,$C25<=AF$23+ANALYSIS!$G$6),1,0) -> 0 | AX25: 0 | AY25: =AX25+AH25 -> 0 | AZ25: =AY25+AI25 -> 1 | BA25: =AZ25+AJ25 -> 1 | BB25: =BA25+AK25 -> 1 | BC25: =BB25+AL25 -> 1 | BD25: =BC25+AM25 -> 1 | BE25: =BD25+AN25 -> 1 | BF25: =BE25+AO25 -> 1 | ... BM25: =BL25+AV25 -> 1
A26: =ANALYSIS!B32 -> 19-02 | B26: =ANALYSIS!E32 -> 58 | C26: =ANALYSIS!G32 -> 24.7 | D26: =IFERROR(MATCH(1,$AH26:$AV26,0),"") -> 10 | R26: {=IF(AX26>0,0,SUMPRODUCT((AX$25:AX$124=0)*($B$25:$B$124>=$B26)*($B$25:$B$124<=$B26+ANALYSIS!$G$5)*($C$25:$C$124>=$C26)*($C$25:$C$124<=$C26+ANALYSIS!$G$6)))} -> 2 | S26: {=IF(AY26>0,0,SUMPRODUCT((AY$25:AY$124=0)*($B$25:$B$124>=$B26)*($B$25:$B$124<=$B26+ANALYSIS!$G$5)*($C$25:$C$124>=$C26)*($C$25:$C$124<=$C26+ANALYSIS!$G$6)))} -> 2 | T26: {=IF(AZ26>0,0,SUMPRODUCT((AZ$25:AZ$124=0)*($B$25:$B$124>=$B26)*($B$25:$B$124<=$B26+ANALYSIS!$G$5)*($C$25:$C$124>=$C26)*($C$25:$C$124<=$C26+ANALYSIS!$G$6)))} -> 2 | U26: {=IF(BA26>0,0,SUMPRODUCT((BA$25:BA$124=0)*($B$25:$B$124>=$B26)*($B$25:$B$124<=$B26+ANALYSIS!$G$5)*($C$25:$C$124>=$C26)*($C$25:$C$124<=$C26+ANALYSIS!$G$6)))} -> 2 | V26: {=IF(BB26>0,0,SUMPRODUCT((BB$25:BB$124=0)*($B$25:$B$124>=$B26)*($B$25:$B$124<=$B26+ANALYSIS!$G$5)*($C$25:$C$124>=$C26)*($C$25:$C$124<=$C26+ANALYSIS!$G$6)))} -> 2 | W26: {=IF(BC26>0,0,SUMPRODUCT((BC$25:BC$124=0)*($B$25:$B$124>=$B26)*($B$25:$B$124<=$B26+ANALYSIS!$G$5)*($C$25:$C$124>=$C26)*($C$25:$C$124<=$C26+ANALYSIS!$G$6)))} -> 2 | X26: {=IF(BD26>0,0,SUMPRODUCT((BD$25:BD$124=0)*($B$25:$B$124>=$B26)*($B$25:$B$124<=$B26+ANALYSIS!$G$5)*($C$25:$C$124>=$C26)*($C$25:$C$124<=$C26+ANALYSIS!$G$6)))} -> 2 | Y26: {=IF(BE26>0,0,SUMPRODUCT((BE$25:BE$124=0)*($B$25:$B$124>=$B26)*($B$25:$B$124<=$B26+ANALYSIS!$G$5)*($C$25:$C$124>=$C26)*($C$25:$C$124<=$C26+ANALYSIS!$G$6)))} -> 2 | ... AF26: {=IF(BL26>0,0,SUMPRODUCT((BL$25:BL$124=0)*($B$25:$B$124>=$B26)*($B$25:$B$124<=$B26+ANALYSIS!$G$5)*($C$25:$C$124>=$C26)*($C$25:$C$124<=$C26+ANALYSIS!$G$6)))} -> 0 | AH26: =IF(AND(AX26=0,$B26>=R$22,$B26<=R$22+ANALYSIS!$G$5,$C26>=R$23,$C26<=R$23+ANALYSIS!$G$6),1,0) -> 0 | AI26: =IF(AND(AY26=0,$B26>=S$22,$B26<=S$22+ANALYSIS!$G$5,$C26>=S$23,$C26<=S$23+ANALYSIS!$G$6),1,0) -> 0 | AJ26: =IF(AND(AZ26=0,$B26>=T$22,$B26<=T$22+ANALYSIS!$G$5,$C26>=T$23,$C26<=T$23+ANALYSIS!$G$6),1,0) -> 0 | AK26: =IF(AND(BA26=0,$B26>=U$22,$B26<=U$22+ANALYSIS!$G$5,$C26>=U$23,$C26<=U$23+ANALYSIS!$G$6),1,0) -> 0 | AL26: =IF(AND(BB26=0,$B26>=V$22,$B26<=V$22+ANALYSIS!$G$5,$C26>=V$23,$C26<=V$23+ANALYSIS!$G$6),1,0) -> 0 | AM26: =IF(AND(BC26=0,$B26>=W$22,$B26<=W$22+ANALYSIS!$G$5,$C26>=W$23,$C26<=W$23+ANALYSIS!$G$6),1,0) -> 0 | AN26: =IF(AND(BD26=0,$B26>=X$22,$B26<=X$22+ANALYSIS!$G$5,$C26>=X$23,$C26<=X$23+ANALYSIS!$G$6),1,0) -> 0 | AO26: =IF(AND(BE26=0,$B26>=Y$22,$B26<=Y$22+ANALYSIS!$G$5,$C26>=Y$23,$C26<=Y$23+ANALYSIS!$G$6),1,0) -> 0 | ... AV26: =IF(AND(BL26=0,$B26>=AF$22,$B26<=AF$22+ANALYSIS!$G$5,$C26>=AF$23,$C26<=AF$23+ANALYSIS!$G$6),1,0) -> 0 | AX26: 0 | AY26: =AX26+AH26 -> 0 | AZ26: =AY26+AI26 -> 0 | BA26: =AZ26+AJ26 -> 0 | BB26: =BA26+AK26 -> 0 | BC26: =BB26+AL26 -> 0 | BD26: =BC26+AM26 -> 0 | BE26: =BD26+AN26 -> 0 | BF26: =BE26+AO26 -> 0 | ... BM26: =BL26+AV26 -> 1
A27: =ANALYSIS!B33 -> 19-03 | B27: =ANALYSIS!E33 -> 52 | C27: =ANALYSIS!G33 -> 22.19 | D27: =IFERROR(MATCH(1,$AH27:$AV27,0),"") -> 13 | R27: {=IF(AX27>0,0,SUMPRODUCT((AX$25:AX$124=0)*($B$25:$B$124>=$B27)*($B$25:$B$124<=$B27+ANALYSIS!$G$5)*($C$25:$C$124>=$C27)*($C$25:$C$124<=$C27+ANALYSIS!$G$6)))} -> 5 | S27: {=IF(AY27>0,0,SUMPRODUCT((AY$25:AY$124=0)*($B$25:$B$124>=$B27)*($B$25:$B$124<=$B27+ANALYSIS!$G$5)*($C$25:$C$124>=$C27)*($C$25:$C$124<=$C27+ANALYSIS!$G$6)))} -> 5 | T27: {=IF(AZ27>0,0,SUMPRODUCT((AZ$25:AZ$124=0)*($B$25:$B$124>=$B27)*($B$25:$B$124<=$B27+ANALYSIS!$G$5)*($C$25:$C$124>=$C27)*($C$25:$C$124<=$C27+ANALYSIS!$G$6)))} -> 5 | U27: {=IF(BA27>0,0,SUMPRODUCT((BA$25:BA$124=0)*($B$25:$B$124>=$B27)*($B$25:$B$124<=$B27+ANALYSIS!$G$5)*($C$25:$C$124>=$C27)*($C$25:$C$124<=$C27+ANALYSIS!$G$6)))} -> 5 | V27: {=IF(BB27>0,0,SUMPRODUCT((BB$25:BB$124=0)*($B$25:$B$124>=$B27)*($B$25:$B$124<=$B27+ANALYSIS!$G$5)*($C$25:$C$124>=$C27)*($C$25:$C$124<=$C27+ANALYSIS!$G$6)))} -> 5 | W27: {=IF(BC27>0,0,SUMPRODUCT((BC$25:BC$124=0)*($B$25:$B$124>=$B27)*($B$25:$B$124<=$B27+ANALYSIS!$G$5)*($C$25:$C$124>=$C27)*($C$25:$C$124<=$C27+ANALYSIS!$G$6)))} -> 3 | X27: {=IF(BD27>0,0,SUMPRODUCT((BD$25:BD$124=0)*($B$25:$B$124>=$B27)*($B$25:$B$124<=$B27+ANALYSIS!$G$5)*($C$25:$C$124>=$C27)*($C$25:$C$124<=$C27+ANALYSIS!$G$6)))} -> 3 | Y27: {=IF(BE27>0,0,SUMPRODUCT((BE$25:BE$124=0)*($B$25:$B$124>=$B27)*($B$25:$B$124<=$B27+ANALYSIS!$G$5)*($C$25:$C$124>=$C27)*($C$25:$C$124<=$C27+ANALYSIS!$G$6)))} -> 2 | ... AF27: {=IF(BL27>0,0,SUMPRODUCT((BL$25:BL$124=0)*($B$25:$B$124>=$B27)*($B$25:$B$124<=$B27+ANALYSIS!$G$5)*($C$25:$C$124>=$C27)*($C$25:$C$124<=$C27+ANALYSIS!$G$6)))} -> 0 | AH27: =IF(AND(AX27=0,$B27>=R$22,$B27<=R$22+ANALYSIS!$G$5,$C27>=R$23,$C27<=R$23+ANALYSIS!$G$6),1,0) -> 0 | AI27: =IF(AND(AY27=0,$B27>=S$22,$B27<=S$22+ANALYSIS!$G$5,$C27>=S$23,$C27<=S$23+ANALYSIS!$G$6),1,0) -> 0 | AJ27: =IF(AND(AZ27=0,$B27>=T$22,$B27<=T$22+ANALYSIS!$G$5,$C27>=T$23,$C27<=T$23+ANALYSIS!$G$6),1,0) -> 0 | AK27: =IF(AND(BA27=0,$B27>=U$22,$B27<=U$22+ANALYSIS!$G$5,$C27>=U$23,$C27<=U$23+ANALYSIS!$G$6),1,0) -> 0 | AL27: =IF(AND(BB27=0,$B27>=V$22,$B27<=V$22+ANALYSIS!$G$5,$C27>=V$23,$C27<=V$23+ANALYSIS!$G$6),1,0) -> 0 | AM27: =IF(AND(BC27=0,$B27>=W$22,$B27<=W$22+ANALYSIS!$G$5,$C27>=W$23,$C27<=W$23+ANALYSIS!$G$6),1,0) -> 0 | AN27: =IF(AND(BD27=0,$B27>=X$22,$B27<=X$22+ANALYSIS!$G$5,$C27>=X$23,$C27<=X$23+ANALYSIS!$G$6),1,0) -> 0 | AO27: =IF(AND(BE27=0,$B27>=Y$22,$B27<=Y$22+ANALYSIS!$G$5,$C27>=Y$23,$C27<=Y$23+ANALYSIS!$G$6),1,0) -> 0 | ... AV27: =IF(AND(BL27=0,$B27>=AF$22,$B27<=AF$22+ANALYSIS!$G$5,$C27>=AF$23,$C27<=AF$23+ANALYSIS!$G$6),1,0) -> 0 | AX27: 0 | AY27: =AX27+AH27 -> 0 | AZ27: =AY27+AI27 -> 0 | BA27: =AZ27+AJ27 -> 0 | BB27: =BA27+AK27 -> 0 | BC27: =BB27+AL27 -> 0 | BD27: =BC27+AM27 -> 0 | BE27: =BD27+AN27 -> 0 | BF27: =BE27+AO27 -> 0 | ... BM27: =BL27+AV27 -> 1
A28: =ANALYSIS!B34 -> 19-04 | B28: =ANALYSIS!E34 -> 55 | C28: =ANALYSIS!G34 -> 24.03 | D28: =IFERROR(MATCH(1,$AH28:$AV28,0),"") -> 1 | R28: {=IF(AX28>0,0,SUMPRODUCT((AX$25:AX$124=0)*($B$25:$B$124>=$B28)*($B$25:$B$124<=$B28+ANALYSIS!$G$5)*($C$25:$C$124>=$C28)*($C$25:$C$124<=$C28+ANALYSIS!$G$6)))} -> 9 | S28: {=IF(AY28>0,0,SUMPRODUCT((AY$25:AY$124=0)*($B$25:$B$124>=$B28)*($B$25:$B$124<=$B28+ANALYSIS!$G$5)*($C$25:$C$124>=$C28)*($C$25:$C$124<=$C28+ANALYSIS!$G$6)))} -> 0 | T28: {=IF(AZ28>0,0,SUMPRODUCT((AZ$25:AZ$124=0)*($B$25:$B$124>=$B28)*($B$25:$B$124<=$B28+ANALYSIS!$G$5)*($C$25:$C$124>=$C28)*($C$25:$C$124<=$C28+ANALYSIS!$G$6)))} -> 0 | U28: {=IF(BA28>0,0,SUMPRODUCT((BA$25:BA$124=0)*($B$25:$B$124>=$B28)*($B$25:$B$124<=$B28+ANALYSIS!$G$5)*($C$25:$C$124>=$C28)*($C$25:$C$124<=$C28+ANALYSIS!$G$6)))} -> 0 | V28: {=IF(BB28>0,0,SUMPRODUCT((BB$25:BB$124=0)*($B$25:$B$124>=$B28)*($B$25:$B$124<=$B28+ANALYSIS!$G$5)*($C$25:$C$124>=$C28)*($C$25:$C$124<=$C28+ANALYSIS!$G$6)))} -> 0 | W28: {=IF(BC28>0,0,SUMPRODUCT((BC$25:BC$124=0)*($B$25:$B$124>=$B28)*($B$25:$B$124<=$B28+ANALYSIS!$G$5)*($C$25:$C$124>=$C28)*($C$25:$C$124<=$C28+ANALYSIS!$G$6)))} -> 0 | X28: {=IF(BD28>0,0,SUMPRODUCT((BD$25:BD$124=0)*($B$25:$B$124>=$B28)*($B$25:$B$124<=$B28+ANALYSIS!$G$5)*($C$25:$C$124>=$C28)*($C$25:$C$124<=$C28+ANALYSIS!$G$6)))} -> 0 | Y28: {=IF(BE28>0,0,SUMPRODUCT((BE$25:BE$124=0)*($B$25:$B$124>=$B28)*($B$25:$B$124<=$B28+ANALYSIS!$G$5)*($C$25:$C$124>=$C28)*($C$25:$C$124<=$C28+ANALYSIS!$G$6)))} -> 0 | ... AF28: {=IF(BL28>0,0,SUMPRODUCT((BL$25:BL$124=0)*($B$25:$B$124>=$B28)*($B$25:$B$124<=$B28+ANALYSIS!$G$5)*($C$25:$C$124>=$C28)*($C$25:$C$124<=$C28+ANALYSIS!$G$6)))} -> 0 | AH28: =IF(AND(AX28=0,$B28>=R$22,$B28<=R$22+ANALYSIS!$G$5,$C28>=R$23,$C28<=R$23+ANALYSIS!$G$6),1,0) -> 1 | AI28: =IF(AND(AY28=0,$B28>=S$22,$B28<=S$22+ANALYSIS!$G$5,$C28>=S$23,$C28<=S$23+ANALYSIS!$G$6),1,0) -> 0 | AJ28: =IF(AND(AZ28=0,$B28>=T$22,$B28<=T$22+ANALYSIS!$G$5,$C28>=T$23,$C28<=T$23+ANALYSIS!$G$6),1,0) -> 0 | AK28: =IF(AND(BA28=0,$B28>=U$22,$B28<=U$22+ANALYSIS!$G$5,$C28>=U$23,$C28<=U$23+ANALYSIS!$G$6),1,0) -> 0 | AL28: =IF(AND(BB28=0,$B28>=V$22,$B28<=V$22+ANALYSIS!$G$5,$C28>=V$23,$C28<=V$23+ANALYSIS!$G$6),1,0) -> 0 | AM28: =IF(AND(BC28=0,$B28>=W$22,$B28<=W$22+ANALYSIS!$G$5,$C28>=W$23,$C28<=W$23+ANALYSIS!$G$6),1,0) -> 0 | AN28: =IF(AND(BD28=0,$B28>=X$22,$B28<=X$22+ANALYSIS!$G$5,$C28>=X$23,$C28<=X$23+ANALYSIS!$G$6),1,0) -> 0 | AO28: =IF(AND(BE28=0,$B28>=Y$22,$B28<=Y$22+ANALYSIS!$G$5,$C28>=Y$23,$C28<=Y$23+ANALYSIS!$G$6),1,0) -> 0 | ... AV28: =IF(AND(BL28=0,$B28>=AF$22,$B28<=AF$22+ANALYSIS!$G$5,$C28>=AF$23,$C28<=AF$23+ANALYSIS!$G$6),1,0) -> 0 | AX28: 0 | AY28: =AX28+AH28 -> 1 | AZ28: =AY28+AI28 -> 1 | BA28: =AZ28+AJ28 -> 1 | BB28: =BA28+AK28 -> 1 | BC28: =BB28+AL28 -> 1 | BD28: =BC28+AM28 -> 1 | BE28: =BD28+AN28 -> 1 | BF28: =BE28+AO28 -> 1 | ... BM28: =BL28+AV28 -> 1
A29: =ANALYSIS!B35 -> 19-05 | B29: =ANALYSIS!E35 -> 56 | C29: =ANALYSIS!G35 -> 21.93 | D29: =IFERROR(MATCH(1,$AH29:$AV29,0),"") -> 4 | R29: {=IF(AX29>0,0,SUMPRODUCT((AX$25:AX$124=0)*($B$25:$B$124>=$B29)*($B$25:$B$124<=$B29+ANALYSIS!$G$5)*($C$25:$C$124>=$C29)*($C$25:$C$124<=$C29+ANALYSIS!$G$6)))} -> 5 | S29: {=IF(AY29>0,0,SUMPRODUCT((AY$25:AY$124=0)*($B$25:$B$124>=$B29)*($B$25:$B$124<=$B29+ANALYSIS!$G$5)*($C$25:$C$124>=$C29)*($C$25:$C$124<=$C29+ANALYSIS!$G$6)))} -> 5 | T29: {=IF(AZ29>0,0,SUMPRODUCT((AZ$25:AZ$124=0)*($B$25:$B$124>=$B29)*($B$25:$B$124<=$B29+ANALYSIS!$G$5)*($C$25:$C$124>=$C29)*($C$25:$C$124<=$C29+ANALYSIS!$G$6)))} -> 5 | U29: {=IF(BA29>0,0,SUMPRODUCT((BA$25:BA$124=0)*($B$25:$B$124>=$B29)*($B$25:$B$124<=$B29+ANALYSIS!$G$5)*($C$25:$C$124>=$C29)*($C$25:$C$124<=$C29+ANALYSIS!$G$6)))} -> 5 | V29: {=IF(BB29>0,0,SUMPRODUCT((BB$25:BB$124=0)*($B$25:$B$124>=$B29)*($B$25:$B$124<=$B29+ANALYSIS!$G$5)*($C$25:$C$124>=$C29)*($C$25:$C$124<=$C29+ANALYSIS!$G$6)))} -> 0 | W29: {=IF(BC29>0,0,SUMPRODUCT((BC$25:BC$124=0)*($B$25:$B$124>=$B29)*($B$25:$B$124<=$B29+ANALYSIS!$G$5)*($C$25:$C$124>=$C29)*($C$25:$C$124<=$C29+ANALYSIS!$G$6)))} -> 0 | X29: {=IF(BD29>0,0,SUMPRODUCT((BD$25:BD$124=0)*($B$25:$B$124>=$B29)*($B$25:$B$124<=$B29+ANALYSIS!$G$5)*($C$25:$C$124>=$C29)*($C$25:$C$124<=$C29+ANALYSIS!$G$6)))} -> 0 | Y29: {=IF(BE29>0,0,SUMPRODUCT((BE$25:BE$124=0)*($B$25:$B$124>=$B29)*($B$25:$B$124<=$B29+ANALYSIS!$G$5)*($C$25:$C$124>=$C29)*($C$25:$C$124<=$C29+ANALYSIS!$G$6)))} -> 0 | ... AF29: {=IF(BL29>0,0,SUMPRODUCT((BL$25:BL$124=0)*($B$25:$B$124>=$B29)*($B$25:$B$124<=$B29+ANALYSIS!$G$5)*($C$25:$C$124>=$C29)*($C$25:$C$124<=$C29+ANALYSIS!$G$6)))} -> 0 | AH29: =IF(AND(AX29=0,$B29>=R$22,$B29<=R$22+ANALYSIS!$G$5,$C29>=R$23,$C29<=R$23+ANALYSIS!$G$6),1,0) -> 0 | AI29: =IF(AND(AY29=0,$B29>=S$22,$B29<=S$22+ANALYSIS!$G$5,$C29>=S$23,$C29<=S$23+ANALYSIS!$G$6),1,0) -> 0 | AJ29: =IF(AND(AZ29=0,$B29>=T$22,$B29<=T$22+ANALYSIS!$G$5,$C29>=T$23,$C29<=T$23+ANALYSIS!$G$6),1,0) -> 0 | AK29: =IF(AND(BA29=0,$B29>=U$22,$B29<=U$22+ANALYSIS!$G$5,$C29>=U$23,$C29<=U$23+ANALYSIS!$G$6),1,0) -> 1 | AL29: =IF(AND(BB29=0,$B29>=V$22,$B29<=V$22+ANALYSIS!$G$5,$C29>=V$23,$C29<=V$23+ANALYSIS!$G$6),1,0) -> 0 | AM29: =IF(AND(BC29=0,$B29>=W$22,$B29<=W$22+ANALYSIS!$G$5,$C29>=W$23,$C29<=W$23+ANALYSIS!$G$6),1,0) -> 0 | AN29: =IF(AND(BD29=0,$B29>=X$22,$B29<=X$22+ANALYSIS!$G$5,$C29>=X$23,$C29<=X$23+ANALYSIS!$G$6),1,0) -> 0 | AO29: =IF(AND(BE29=0,$B29>=Y$22,$B29<=Y$22+ANALYSIS!$G$5,$C29>=Y$23,$C29<=Y$23+ANALYSIS!$G$6),1,0) -> 0 | ... AV29: =IF(AND(BL29=0,$B29>=AF$22,$B29<=AF$22+ANALYSIS!$G$5,$C29>=AF$23,$C29<=AF$23+ANALYSIS!$G$6),1,0) -> 0 | AX29: 0 | AY29: =AX29+AH29 -> 0 | AZ29: =AY29+AI29 -> 0 | BA29: =AZ29+AJ29 -> 0 | BB29: =BA29+AK29 -> 1 | BC29: =BB29+AL29 -> 1 | BD29: =BC29+AM29 -> 1 | BE29: =BD29+AN29 -> 1 | BF29: =BE29+AO29 -> 1 | ... BM29: =BL29+AV29 -> 1
A30: =ANALYSIS!B36 -> 19-06 | B30: =ANALYSIS!E36 -> 55 | C30: =ANALYSIS!G36 -> 23.85 | D30: =IFERROR(MATCH(1,$AH30:$AV30,0),"") -> 1 | R30: {=IF(AX30>0,0,SUMPRODUCT((AX$25:AX$124=0)*($B$25:$B$124>=$B30)*($B$25:$B$124<=$B30+ANALYSIS!$G$5)*($C$25:$C$124>=$C30)*($C$25:$C$124<=$C30+ANALYSIS!$G$6)))} -> 14 | S30: {=IF(AY30>0,0,SUMPRODUCT((AY$25:AY$124=0)*($B$25:$B$124>=$B30)*($B$25:$B$124<=$B30+ANALYSIS!$G$5)*($C$25:$C$124>=$C30)*($C$25:$C$124<=$C30+ANALYSIS!$G$6)))} -> 0 | T30: {=IF(AZ30>0,0,SUMPRODUCT((AZ$25:AZ$124=0)*($B$25:$B$124>=$B30)*($B$25:$B$124<=$B30+ANALYSIS!$G$5)*($C$25:$C$124>=$C30)*($C$25:$C$124<=$C30+ANALYSIS!$G$6)))} -> 0 | U30: {=IF(BA30>0,0,SUMPRODUCT((BA$25:BA$124=0)*($B$25:$B$124>=$B30)*($B$25:$B$124<=$B30+ANALYSIS!$G$5)*($C$25:$C$124>=$C30)*($C$25:$C$124<=$C30+ANALYSIS!$G$6)))} -> 0 | V30: {=IF(BB30>0,0,SUMPRODUCT((BB$25:BB$124=0)*($B$25:$B$124>=$B30)*($B$25:$B$124<=$B30+ANALYSIS!$G$5)*($C$25:$C$124>=$C30)*($C$25:$C$124<=$C30+ANALYSIS!$G$6)))} -> 0 | W30: {=IF(BC30>0,0,SUMPRODUCT((BC$25:BC$124=0)*($B$25:$B$124>=$B30)*($B$25:$B$124<=$B30+ANALYSIS!$G$5)*($C$25:$C$124>=$C30)*($C$25:$C$124<=$C30+ANALYSIS!$G$6)))} -> 0 | X30: {=IF(BD30>0,0,SUMPRODUCT((BD$25:BD$124=0)*($B$25:$B$124>=$B30)*($B$25:$B$124<=$B30+ANALYSIS!$G$5)*($C$25:$C$124>=$C30)*($C$25:$C$124<=$C30+ANALYSIS!$G$6)))} -> 0 | Y30: {=IF(BE30>0,0,SUMPRODUCT((BE$25:BE$124=0)*($B$25:$B$124>=$B30)*($B$25:$B$124<=$B30+ANALYSIS!$G$5)*($C$25:$C$124>=$C30)*($C$25:$C$124<=$C30+ANALYSIS!$G$6)))} -> 0 | ... AF30: {=IF(BL30>0,0,SUMPRODUCT((BL$25:BL$124=0)*($B$25:$B$124>=$B30)*($B$25:$B$124<=$B30+ANALYSIS!$G$5)*($C$25:$C$124>=$C30)*($C$25:$C$124<=$C30+ANALYSIS!$G$6)))} -> 0 | AH30: =IF(AND(AX30=0,$B30>=R$22,$B30<=R$22+ANALYSIS!$G$5,$C30>=R$23,$C30<=R$23+ANALYSIS!$G$6),1,0) -> 1 | AI30: =IF(AND(AY30=0,$B30>=S$22,$B30<=S$22+ANALYSIS!$G$5,$C30>=S$23,$C30<=S$23+ANALYSIS!$G$6),1,0) -> 0 | AJ30: =IF(AND(AZ30=0,$B30>=T$22,$B30<=T$22+ANALYSIS!$G$5,$C30>=T$23,$C30<=T$23+ANALYSIS!$G$6),1,0) -> 0 | AK30: =IF(AND(BA30=0,$B30>=U$22,$B30<=U$22+ANALYSIS!$G$5,$C30>=U$23,$C30<=U$23+ANALYSIS!$G$6),1,0) -> 0 | AL30: =IF(AND(BB30=0,$B30>=V$22,$B30<=V$22+ANALYSIS!$G$5,$C30>=V$23,$C30<=V$23+ANALYSIS!$G$6),1,0) -> 0 | AM30: =IF(AND(BC30=0,$B30>=W$22,$B30<=W$22+ANALYSIS!$G$5,$C30>=W$23,$C30<=W$23+ANALYSIS!$G$6),1,0) -> 0 | AN30: =IF(AND(BD30=0,$B30>=X$22,$B30<=X$22+ANALYSIS!$G$5,$C30>=X$23,$C30<=X$23+ANALYSIS!$G$6),1,0) -> 0 | AO30: =IF(AND(BE30=0,$B30>=Y$22,$B30<=Y$22+ANALYSIS!$G$5,$C30>=Y$23,$C30<=Y$23+ANALYSIS!$G$6),1,0) -> 0 | ... AV30: =IF(AND(BL30=0,$B30>=AF$22,$B30<=AF$22+ANALYSIS!$G$5,$C30>=AF$23,$C30<=AF$23+ANALYSIS!$G$6),1,0) -> 0 | AX30: 0 | AY30: =AX30+AH30 -> 1 | AZ30: =AY30+AI30 -> 1 | BA30: =AZ30+AJ30 -> 1 | BB30: =BA30+AK30 -> 1 | BC30: =BB30+AL30 -> 1 | BD30: =BC30+AM30 -> 1 | BE30: =BD30+AN30 -> 1 | BF30: =BE30+AO30 -> 1 | ... BM30: =BL30+AV30 -> 1
A31: =ANALYSIS!B37 -> 19-07 | B31: =ANALYSIS!E37 -> 52 | C31: =ANALYSIS!G37 -> 21.59 | D31: =IFERROR(MATCH(1,$AH31:$AV31,0),"") -> 14 | R31: {=IF(AX31>0,0,SUMPRODUCT((AX$25:AX$124=0)*($B$25:$B$124>=$B31)*($B$25:$B$124<=$B31+ANALYSIS!$G$5)*($C$25:$C$124>=$C31)*($C$25:$C$124<=$C31+ANALYSIS!$G$6)))} -> 5 | S31: {=IF(AY31>0,0,SUMPRODUCT((AY$25:AY$124=0)*($B$25:$B$124>=$B31)*($B$25:$B$124<=$B31+ANALYSIS!$G$5)*($C$25:$C$124>=$C31)*($C$25:$C$124<=$C31+ANALYSIS!$G$6)))} -> 5 | T31: {=IF(AZ31>0,0,SUMPRODUCT((AZ$25:AZ$124=0)*($B$25:$B$124>=$B31)*($B$25:$B$124<=$B31+ANALYSIS!$G$5)*($C$25:$C$124>=$C31)*($C$25:$C$124<=$C31+ANALYSIS!$G$6)))} -> 5 | U31: {=IF(BA31>0,0,SUMPRODUCT((BA$25:BA$124=0)*($B$25:$B$124>=$B31)*($B$25:$B$124<=$B31+ANALYSIS!$G$5)*($C$25:$C$124>=$C31)*($C$25:$C$124<=$C31+ANALYSIS!$G$6)))} -> 5 | V31: {=IF(BB31>0,0,SUMPRODUCT((BB$25:BB$124=0)*($B$25:$B$124>=$B31)*($B$25:$B$124<=$B31+ANALYSIS!$G$5)*($C$25:$C$124>=$C31)*($C$25:$C$124<=$C31+ANALYSIS!$G$6)))} -> 3 | W31: {=IF(BC31>0,0,SUMPRODUCT((BC$25:BC$124=0)*($B$25:$B$124>=$B31)*($B$25:$B$124<=$B31+ANALYSIS!$G$5)*($C$25:$C$124>=$C31)*($C$25:$C$124<=$C31+ANALYSIS!$G$6)))} -> 2 | X31: {=IF(BD31>0,0,SUMPRODUCT((BD$25:BD$124=0)*($B$25:$B$124>=$B31)*($B$25:$B$124<=$B31+ANALYSIS!$G$5)*($C$25:$C$124>=$C31)*($C$25:$C$124<=$C31+ANALYSIS!$G$6)))} -> 2 | Y31: {=IF(BE31>0,0,SUMPRODUCT((BE$25:BE$124=0)*($B$25:$B$124>=$B31)*($B$25:$B$124<=$B31+ANALYSIS!$G$5)*($C$25:$C$124>=$C31)*($C$25:$C$124<=$C31+ANALYSIS!$G$6)))} -> 2 | ... AF31: {=IF(BL31>0,0,SUMPRODUCT((BL$25:BL$124=0)*($B$25:$B$124>=$B31)*($B$25:$B$124<=$B31+ANALYSIS!$G$5)*($C$25:$C$124>=$C31)*($C$25:$C$124<=$C31+ANALYSIS!$G$6)))} -> 0 | AH31: =IF(AND(AX31=0,$B31>=R$22,$B31<=R$22+ANALYSIS!$G$5,$C31>=R$23,$C31<=R$23+ANALYSIS!$G$6),1,0) -> 0 | AI31: =IF(AND(AY31=0,$B31>=S$22,$B31<=S$22+ANALYSIS!$G$5,$C31>=S$23,$C31<=S$23+ANALYSIS!$G$6),1,0) -> 0 | AJ31: =IF(AND(AZ31=0,$B31>=T$22,$B31<=T$22+ANALYSIS!$G$5,$C31>=T$23,$C31<=T$23+ANALYSIS!$G$6),1,0) -> 0 | AK31: =IF(AND(BA31=0,$B31>=U$22,$B31<=U$22+ANALYSIS!$G$5,$C31>=U$23,$C31<=U$23+ANALYSIS!$G$6),1,0) -> 0 | AL31: =IF(AND(BB31=0,$B31>=V$22,$B31<=V$22+ANALYSIS!$G$5,$C31>=V$23,$C31<=V$23+ANALYSIS!$G$6),1,0) -> 0 | AM31: =IF(AND(BC31=0,$B31>=W$22,$B31<=W$22+ANALYSIS!$G$5,$C31>=W$23,$C31<=W$23+ANALYSIS!$G$6),1,0) -> 0 | AN31: =IF(AND(BD31=0,$B31>=X$22,$B31<=X$22+ANALYSIS!$G$5,$C31>=X$23,$C31<=X$23+ANALYSIS!$G$6),1,0) -> 0 | AO31: =IF(AND(BE31=0,$B31>=Y$22,$B31<=Y$22+ANALYSIS!$G$5,$C31>=Y$23,$C31<=Y$23+ANALYSIS!$G$6),1,0) -> 0 | ... AV31: =IF(AND(BL31=0,$B31>=AF$22,$B31<=AF$22+ANALYSIS!$G$5,$C31>=AF$23,$C31<=AF$23+ANALYSIS!$G$6),1,0) -> 0 | AX31: 0 | AY31: =AX31+AH31 -> 0 | AZ31: =AY31+AI31 -> 0 | BA31: =AZ31+AJ31 -> 0 | BB31: =BA31+AK31 -> 0 | BC31: =BB31+AL31 -> 0 | BD31: =BC31+AM31 -> 0 | BE31: =BD31+AN31 -> 0 | BF31: =BE31+AO31 -> 0 | ... BM31: =BL31+AV31 -> 1
A32: =ANALYSIS!B38 -> 19-08 | B32: =ANALYSIS!E38 -> 53 | C32: =ANALYSIS!G38 -> 21.54 | D32: =IFERROR(MATCH(1,$AH32:$AV32,0),"") -> 4 | R32: {=IF(AX32>0,0,SUMPRODUCT((AX$25:AX$124=0)*($B$25:$B$124>=$B32)*($B$25:$B$124<=$B32+ANALYSIS!$G$5)*($C$25:$C$124>=$C32)*($C$25:$C$124<=$C32+ANALYSIS!$G$6)))} -> 6 | S32: {=IF(AY32>0,0,SUMPRODUCT((AY$25:AY$124=0)*($B$25:$B$124>=$B32)*($B$25:$B$124<=$B32+ANALYSIS!$G$5)*($C$25:$C$124>=$C32)*($C$25:$C$124<=$C32+ANALYSIS!$G$6)))} -> 6 | T32: {=IF(AZ32>0,0,SUMPRODUCT((AZ$25:AZ$124=0)*($B$25:$B$124>=$B32)*($B$25:$B$124<=$B32+ANALYSIS!$G$5)*($C$25:$C$124>=$C32)*($C$25:$C$124<=$C32+ANALYSIS!$G$6)))} -> 6 | U32: {=IF(BA32>0,0,SUMPRODUCT((BA$25:BA$124=0)*($B$25:$B$124>=$B32)*($B$25:$B$124<=$B32+ANALYSIS!$G$5)*($C$25:$C$124>=$C32)*($C$25:$C$124<=$C32+ANALYSIS!$G$6)))} -> 6 | V32: {=IF(BB32>0,0,SUMPRODUCT((BB$25:BB$124=0)*($B$25:$B$124>=$B32)*($B$25:$B$124<=$B32+ANALYSIS!$G$5)*($C$25:$C$124>=$C32)*($C$25:$C$124<=$C32+ANALYSIS!$G$6)))} -> 0 | W32: {=IF(BC32>0,0,SUMPRODUCT((BC$25:BC$124=0)*($B$25:$B$124>=$B32)*($B$25:$B$124<=$B32+ANALYSIS!$G$5)*($C$25:$C$124>=$C32)*($C$25:$C$124<=$C32+ANALYSIS!$G$6)))} -> 0 | X32: {=IF(BD32>0,0,SUMPRODUCT((BD$25:BD$124=0)*($B$25:$B$124>=$B32)*($B$25:$B$124<=$B32+ANALYSIS!$G$5)*($C$25:$C$124>=$C32)*($C$25:$C$124<=$C32+ANALYSIS!$G$6)))} -> 0 | Y32: {=IF(BE32>0,0,SUMPRODUCT((BE$25:BE$124=0)*($B$25:$B$124>=$B32)*($B$25:$B$124<=$B32+ANALYSIS!$G$5)*($C$25:$C$124>=$C32)*($C$25:$C$124<=$C32+ANALYSIS!$G$6)))} -> 0 | ... AF32: {=IF(BL32>0,0,SUMPRODUCT((BL$25:BL$124=0)*($B$25:$B$124>=$B32)*($B$25:$B$124<=$B32+ANALYSIS!$G$5)*($C$25:$C$124>=$C32)*($C$25:$C$124<=$C32+ANALYSIS!$G$6)))} -> 0 | AH32: =IF(AND(AX32=0,$B32>=R$22,$B32<=R$22+ANALYSIS!$G$5,$C32>=R$23,$C32<=R$23+ANALYSIS!$G$6),1,0) -> 0 | AI32: =IF(AND(AY32=0,$B32>=S$22,$B32<=S$22+ANALYSIS!$G$5,$C32>=S$23,$C32<=S$23+ANALYSIS!$G$6),1,0) -> 0 | AJ32: =IF(AND(AZ32=0,$B32>=T$22,$B32<=T$22+ANALYSIS!$G$5,$C32>=T$23,$C32<=T$23+ANALYSIS!$G$6),1,0) -> 0 | AK32: =IF(AND(BA32=0,$B32>=U$22,$B32<=U$22+ANALYSIS!$G$5,$C32>=U$23,$C32<=U$23+ANALYSIS!$G$6),1,0) -> 1 | AL32: =IF(AND(BB32=0,$B32>=V$22,$B32<=V$22+ANALYSIS!$G$5,$C32>=V$23,$C32<=V$23+ANALYSIS!$G$6),1,0) -> 0 | AM32: =IF(AND(BC32=0,$B32>=W$22,$B32<=W$22+ANALYSIS!$G$5,$C32>=W$23,$C32<=W$23+ANALYSIS!$G$6),1,0) -> 0 | AN32: =IF(AND(BD32=0,$B32>=X$22,$B32<=X$22+ANALYSIS!$G$5,$C32>=X$23,$C32<=X$23+ANALYSIS!$G$6),1,0) -> 0 | AO32: =IF(AND(BE32=0,$B32>=Y$22,$B32<=Y$22+ANALYSIS!$G$5,$C32>=Y$23,$C32<=Y$23+ANALYSIS!$G$6),1,0) -> 0 | ... AV32: =IF(AND(BL32=0,$B32>=AF$22,$B32<=AF$22+ANALYSIS!$G$5,$C32>=AF$23,$C32<=AF$23+ANALYSIS!$G$6),1,0) -> 0 | AX32: 0 | AY32: =AX32+AH32 -> 0 | AZ32: =AY32+AI32 -> 0 | BA32: =AZ32+AJ32 -> 0 | BB32: =BA32+AK32 -> 1 | BC32: =BB32+AL32 -> 1 | BD32: =BC32+AM32 -> 1 | BE32: =BD32+AN32 -> 1 | BF32: =BE32+AO32 -> 1 | ... BM32: =BL32+AV32 -> 1
A33: =ANALYSIS!B39 -> 19-09 | B33: =ANALYSIS!E39 -> 50 | C33: =ANALYSIS!G39 -> 22.67 | D33: =IFERROR(MATCH(1,$AH33:$AV33,0),"") -> 8 | R33: {=IF(AX33>0,0,SUMPRODUCT((AX$25:AX$124=0)*($B$25:$B$124>=$B33)*($B$25:$B$124<=$B33+ANALYSIS!$G$5)*($C$25:$C$124>=$C33)*($C$25:$C$124<=$C33+ANALYSIS!$G$6)))} -> 6 | S33: {=IF(AY33>0,0,SUMPRODUCT((AY$25:AY$124=0)*($B$25:$B$124>=$B33)*($B$25:$B$124<=$B33+ANALYSIS!$G$5)*($C$25:$C$124>=$C33)*($C$25:$C$124<=$C33+ANALYSIS!$G$6)))} -> 6 | T33: {=IF(AZ33>0,0,SUMPRODUCT((AZ$25:AZ$124=0)*($B$25:$B$124>=$B33)*($B$25:$B$124<=$B33+ANALYSIS!$G$5)*($C$25:$C$124>=$C33)*($C$25:$C$124<=$C33+ANALYSIS!$G$6)))} -> 4 | U33: {=IF(BA33>0,0,SUMPRODUCT((BA$25:BA$124=0)*($B$25:$B$124>=$B33)*($B$25:$B$124<=$B33+ANALYSIS!$G$5)*($C$25:$C$124>=$C33)*($C$25:$C$124<=$C33+ANALYSIS!$G$6)))} -> 4 | V33: {=IF(BB33>0,0,SUMPRODUCT((BB$25:BB$124=0)*($B$25:$B$124>=$B33)*($B$25:$B$124<=$B33+ANALYSIS!$G$5)*($C$25:$C$124>=$C33)*($C$25:$C$124<=$C33+ANALYSIS!$G$6)))} -> 4 | W33: {=IF(BC33>0,0,SUMPRODUCT((BC$25:BC$124=0)*($B$25:$B$124>=$B33)*($B$25:$B$124<=$B33+ANALYSIS!$G$5)*($C$25:$C$124>=$C33)*($C$25:$C$124<=$C33+ANALYSIS!$G$6)))} -> 4 | X33: {=IF(BD33>0,0,SUMPRODUCT((BD$25:BD$124=0)*($B$25:$B$124>=$B33)*($B$25:$B$124<=$B33+ANALYSIS!$G$5)*($C$25:$C$124>=$C33)*($C$25:$C$124<=$C33+ANALYSIS!$G$6)))} -> 4 | Y33: {=IF(BE33>0,0,SUMPRODUCT((BE$25:BE$124=0)*($B$25:$B$124>=$B33)*($B$25:$B$124<=$B33+ANALYSIS!$G$5)*($C$25:$C$124>=$C33)*($C$25:$C$124<=$C33+ANALYSIS!$G$6)))} -> 4 | ... AF33: {=IF(BL33>0,0,SUMPRODUCT((BL$25:BL$124=0)*($B$25:$B$124>=$B33)*($B$25:$B$124<=$B33+ANALYSIS!$G$5)*($C$25:$C$124>=$C33)*($C$25:$C$124<=$C33+ANALYSIS!$G$6)))} -> 0 | AH33: =IF(AND(AX33=0,$B33>=R$22,$B33<=R$22+ANALYSIS!$G$5,$C33>=R$23,$C33<=R$23+ANALYSIS!$G$6),1,0) -> 0 | AI33: =IF(AND(AY33=0,$B33>=S$22,$B33<=S$22+ANALYSIS!$G$5,$C33>=S$23,$C33<=S$23+ANALYSIS!$G$6),1,0) -> 0 | AJ33: =IF(AND(AZ33=0,$B33>=T$22,$B33<=T$22+ANALYSIS!$G$5,$C33>=T$23,$C33<=T$23+ANALYSIS!$G$6),1,0) -> 0 | AK33: =IF(AND(BA33=0,$B33>=U$22,$B33<=U$22+ANALYSIS!$G$5,$C33>=U$23,$C33<=U$23+ANALYSIS!$G$6),1,0) -> 0 | AL33: =IF(AND(BB33=0,$B33>=V$22,$B33<=V$22+ANALYSIS!$G$5,$C33>=V$23,$C33<=V$23+ANALYSIS!$G$6),1,0) -> 0 | AM33: =IF(AND(BC33=0,$B33>=W$22,$B33<=W$22+ANALYSIS!$G$5,$C33>=W$23,$C33<=W$23+ANALYSIS!$G$6),1,0) -> 0 | AN33: =IF(AND(BD33=0,$B33>=X$22,$B33<=X$22+ANALYSIS!$G$5,$C33>=X$23,$C33<=X$23+ANALYSIS!$G$6),1,0) -> 0 | AO33: =IF(AND(BE33=0,$B33>=Y$22,$B33<=Y$22+ANALYSIS!$G$5,$C33>=Y$23,$C33<=Y$23+ANALYSIS!$G$6),1,0) -> 1 | ... AV33: =IF(AND(BL33=0,$B33>=AF$22,$B33<=AF$22+ANALYSIS!$G$5,$C33>=AF$23,$C33<=AF$23+ANALYSIS!$G$6),1,0) -> 0 | AX33: 0 | AY33: =AX33+AH33 -> 0 | AZ33: =AY33+AI33 -> 0 | BA33: =AZ33+AJ33 -> 0 | BB33: =BA33+AK33 -> 0 | BC33: =BB33+AL33 -> 0 | BD33: =BC33+AM33 -> 0 | BE33: =BD33+AN33 -> 0 | BF33: =BE33+AO33 -> 1 | ... BM33: =BL33+AV33 -> 1
A34: =ANALYSIS!B40 -> 19-10 | B34: =ANALYSIS!E40 -> 56 | C34: =ANALYSIS!G40 -> 24.67 | D34: =IFERROR(MATCH(1,$AH34:$AV34,0),"") -> 10 | R34: {=IF(AX34>0,0,SUMPRODUCT((AX$25:AX$124=0)*($B$25:$B$124>=$B34)*($B$25:$B$124<=$B34+ANALYSIS!$G$5)*($C$25:$C$124>=$C34)*($C$25:$C$124<=$C34+ANALYSIS!$G$6)))} -> 5 | S34: {=IF(AY34>0,0,SUMPRODUCT((AY$25:AY$124=0)*($B$25:$B$124>=$B34)*($B$25:$B$124<=$B34+ANALYSIS!$G$5)*($C$25:$C$124>=$C34)*($C$25:$C$124<=$C34+ANALYSIS!$G$6)))} -> 5 | T34: {=IF(AZ34>0,0,SUMPRODUCT((AZ$25:AZ$124=0)*($B$25:$B$124>=$B34)*($B$25:$B$124<=$B34+ANALYSIS!$G$5)*($C$25:$C$124>=$C34)*($C$25:$C$124<=$C34+ANALYSIS!$G$6)))} -> 5 | U34: {=IF(BA34>0,0,SUMPRODUCT((BA$25:BA$124=0)*($B$25:$B$124>=$B34)*($B$25:$B$124<=$B34+ANALYSIS!$G$5)*($C$25:$C$124>=$C34)*($C$25:$C$124<=$C34+ANALYSIS!$G$6)))} -> 3 | V34: {=IF(BB34>0,0,SUMPRODUCT((BB$25:BB$124=0)*($B$25:$B$124>=$B34)*($B$25:$B$124<=$B34+ANALYSIS!$G$5)*($C$25:$C$124>=$C34)*($C$25:$C$124<=$C34+ANALYSIS!$G$6)))} -> 3 | W34: {=IF(BC34>0,0,SUMPRODUCT((BC$25:BC$124=0)*($B$25:$B$124>=$B34)*($B$25:$B$124<=$B34+ANALYSIS!$G$5)*($C$25:$C$124>=$C34)*($C$25:$C$124<=$C34+ANALYSIS!$G$6)))} -> 3 | X34: {=IF(BD34>0,0,SUMPRODUCT((BD$25:BD$124=0)*($B$25:$B$124>=$B34)*($B$25:$B$124<=$B34+ANALYSIS!$G$5)*($C$25:$C$124>=$C34)*($C$25:$C$124<=$C34+ANALYSIS!$G$6)))} -> 3 | Y34: {=IF(BE34>0,0,SUMPRODUCT((BE$25:BE$124=0)*($B$25:$B$124>=$B34)*($B$25:$B$124<=$B34+ANALYSIS!$G$5)*($C$25:$C$124>=$C34)*($C$25:$C$124<=$C34+ANALYSIS!$G$6)))} -> 3 | ... AF34: {=IF(BL34>0,0,SUMPRODUCT((BL$25:BL$124=0)*($B$25:$B$124>=$B34)*($B$25:$B$124<=$B34+ANALYSIS!$G$5)*($C$25:$C$124>=$C34)*($C$25:$C$124<=$C34+ANALYSIS!$G$6)))} -> 0 | AH34: =IF(AND(AX34=0,$B34>=R$22,$B34<=R$22+ANALYSIS!$G$5,$C34>=R$23,$C34<=R$23+ANALYSIS!$G$6),1,0) -> 0 | AI34: =IF(AND(AY34=0,$B34>=S$22,$B34<=S$22+ANALYSIS!$G$5,$C34>=S$23,$C34<=S$23+ANALYSIS!$G$6),1,0) -> 0 | AJ34: =IF(AND(AZ34=0,$B34>=T$22,$B34<=T$22+ANALYSIS!$G$5,$C34>=T$23,$C34<=T$23+ANALYSIS!$G$6),1,0) -> 0 | AK34: =IF(AND(BA34=0,$B34>=U$22,$B34<=U$22+ANALYSIS!$G$5,$C34>=U$23,$C34<=U$23+ANALYSIS!$G$6),1,0) -> 0 | AL34: =IF(AND(BB34=0,$B34>=V$22,$B34<=V$22+ANALYSIS!$G$5,$C34>=V$23,$C34<=V$23+ANALYSIS!$G$6),1,0) -> 0 | AM34: =IF(AND(BC34=0,$B34>=W$22,$B34<=W$22+ANALYSIS!$G$5,$C34>=W$23,$C34<=W$23+ANALYSIS!$G$6),1,0) -> 0 | AN34: =IF(AND(BD34=0,$B34>=X$22,$B34<=X$22+ANALYSIS!$G$5,$C34>=X$23,$C34<=X$23+ANALYSIS!$G$6),1,0) -> 0 | AO34: =IF(AND(BE34=0,$B34>=Y$22,$B34<=Y$22+ANALYSIS!$G$5,$C34>=Y$23,$C34<=Y$23+ANALYSIS!$G$6),1,0) -> 0 | ... AV34: =IF(AND(BL34=0,$B34>=AF$22,$B34<=AF$22+ANALYSIS!$G$5,$C34>=AF$23,$C34<=AF$23+ANALYSIS!$G$6),1,0) -> 0 | AX34: 0 | AY34: =AX34+AH34 -> 0 | AZ34: =AY34+AI34 -> 0 | BA34: =AZ34+AJ34 -> 0 | BB34: =BA34+AK34 -> 0 | BC34: =BB34+AL34 -> 0 | BD34: =BC34+AM34 -> 0 | BE34: =BD34+AN34 -> 0 | BF34: =BE34+AO34 -> 0 | ... BM34: =BL34+AV34 -> 1
A35: =ANALYSIS!B41 -> 19-11 | B35: =ANALYSIS!E41 -> 52 | C35: =ANALYSIS!G41 -> 23.14 | D35: =IFERROR(MATCH(1,$AH35:$AV35,0),"") -> 8 | R35: {=IF(AX35>0,0,SUMPRODUCT((AX$25:AX$124=0)*($B$25:$B$124>=$B35)*($B$25:$B$124<=$B35+ANALYSIS!$G$5)*($C$25:$C$124>=$C35)*($C$25:$C$124<=$C35+ANALYSIS!$G$6)))} -> 5 | S35: {=IF(AY35>0,0,SUMPRODUCT((AY$25:AY$124=0)*($B$25:$B$124>=$B35)*($B$25:$B$124<=$B35+ANALYSIS!$G$5)*($C$25:$C$124>=$C35)*($C$25:$C$124<=$C35+ANALYSIS!$G$6)))} -> 5 | T35: {=IF(AZ35>0,0,SUMPRODUCT((AZ$25:AZ$124=0)*($B$25:$B$124>=$B35)*($B$25:$B$124<=$B35+ANALYSIS!$G$5)*($C$25:$C$124>=$C35)*($C$25:$C$124<=$C35+ANALYSIS!$G$6)))} -> 2 | U35: {=IF(BA35>0,0,SUMPRODUCT((BA$25:BA$124=0)*($B$25:$B$124>=$B35)*($B$25:$B$124<=$B35+ANALYSIS!$G$5)*($C$25:$C$124>=$C35)*($C$25:$C$124<=$C35+ANALYSIS!$G$6)))} -> 2 | V35: {=IF(BB35>0,0,SUMPRODUCT((BB$25:BB$124=0)*($B$25:$B$124>=$B35)*($B$25:$B$124<=$B35+ANALYSIS!$G$5)*($C$25:$C$124>=$C35)*($C$25:$C$124<=$C35+ANALYSIS!$G$6)))} -> 2 | W35: {=IF(BC35>0,0,SUMPRODUCT((BC$25:BC$124=0)*($B$25:$B$124>=$B35)*($B$25:$B$124<=$B35+ANALYSIS!$G$5)*($C$25:$C$124>=$C35)*($C$25:$C$124<=$C35+ANALYSIS!$G$6)))} -> 2 | X35: {=IF(BD35>0,0,SUMPRODUCT((BD$25:BD$124=0)*($B$25:$B$124>=$B35)*($B$25:$B$124<=$B35+ANALYSIS!$G$5)*($C$25:$C$124>=$C35)*($C$25:$C$124<=$C35+ANALYSIS!$G$6)))} -> 1 | Y35: {=IF(BE35>0,0,SUMPRODUCT((BE$25:BE$124=0)*($B$25:$B$124>=$B35)*($B$25:$B$124<=$B35+ANALYSIS!$G$5)*($C$25:$C$124>=$C35)*($C$25:$C$124<=$C35+ANALYSIS!$G$6)))} -> 1 | ... AF35: {=IF(BL35>0,0,SUMPRODUCT((BL$25:BL$124=0)*($B$25:$B$124>=$B35)*($B$25:$B$124<=$B35+ANALYSIS!$G$5)*($C$25:$C$124>=$C35)*($C$25:$C$124<=$C35+ANALYSIS!$G$6)))} -> 0 | AH35: =IF(AND(AX35=0,$B35>=R$22,$B35<=R$22+ANALYSIS!$G$5,$C35>=R$23,$C35<=R$23+ANALYSIS!$G$6),1,0) -> 0 | AI35: =IF(AND(AY35=0,$B35>=S$22,$B35<=S$22+ANALYSIS!$G$5,$C35>=S$23,$C35<=S$23+ANALYSIS!$G$6),1,0) -> 0 | AJ35: =IF(AND(AZ35=0,$B35>=T$22,$B35<=T$22+ANALYSIS!$G$5,$C35>=T$23,$C35<=T$23+ANALYSIS!$G$6),1,0) -> 0 | AK35: =IF(AND(BA35=0,$B35>=U$22,$B35<=U$22+ANALYSIS!$G$5,$C35>=U$23,$C35<=U$23+ANALYSIS!$G$6),1,0) -> 0 | AL35: =IF(AND(BB35=0,$B35>=V$22,$B35<=V$22+ANALYSIS!$G$5,$C35>=V$23,$C35<=V$23+ANALYSIS!$G$6),1,0) -> 0 | AM35: =IF(AND(BC35=0,$B35>=W$22,$B35<=W$22+ANALYSIS!$G$5,$C35>=W$23,$C35<=W$23+ANALYSIS!$G$6),1,0) -> 0 | AN35: =IF(AND(BD35=0,$B35>=X$22,$B35<=X$22+ANALYSIS!$G$5,$C35>=X$23,$C35<=X$23+ANALYSIS!$G$6),1,0) -> 0 | AO35: =IF(AND(BE35=0,$B35>=Y$22,$B35<=Y$22+ANALYSIS!$G$5,$C35>=Y$23,$C35<=Y$23+ANALYSIS!$G$6),1,0) -> 1 | ... AV35: =IF(AND(BL35=0,$B35>=AF$22,$B35<=AF$22+ANALYSIS!$G$5,$C35>=AF$23,$C35<=AF$23+ANALYSIS!$G$6),1,0) -> 0 | AX35: 0 | AY35: =AX35+AH35 -> 0 | AZ35: =AY35+AI35 -> 0 | BA35: =AZ35+AJ35 -> 0 | BB35: =BA35+AK35 -> 0 | BC35: =BB35+AL35 -> 0 | BD35: =BC35+AM35 -> 0 | BE35: =BD35+AN35 -> 0 | BF35: =BE35+AO35 -> 1 | ... BM35: =BL35+AV35 -> 1
A36: =ANALYSIS!B42 -> 19-12 | B36: =ANALYSIS!E42 -> 57.5 | C36: =ANALYSIS!G42 -> 24.3 | D36: =IFERROR(MATCH(1,$AH36:$AV36,0),"") -> 1 | R36: {=IF(AX36>0,0,SUMPRODUCT((AX$25:AX$124=0)*($B$25:$B$124>=$B36)*($B$25:$B$124<=$B36+ANALYSIS!$G$5)*($C$25:$C$124>=$C36)*($C$25:$C$124<=$C36+ANALYSIS!$G$6)))} -> 4 | S36: {=IF(AY36>0,0,SUMPRODUCT((AY$25:AY$124=0)*($B$25:$B$124>=$B36)*($B$25:$B$124<=$B36+ANALYSIS!$G$5)*($C$25:$C$124>=$C36)*($C$25:$C$124<=$C36+ANALYSIS!$G$6)))} -> 0 | T36: {=IF(AZ36>0,0,SUMPRODUCT((AZ$25:AZ$124=0)*($B$25:$B$124>=$B36)*($B$25:$B$124<=$B36+ANALYSIS!$G$5)*($C$25:$C$124>=$C36)*($C$25:$C$124<=$C36+ANALYSIS!$G$6)))} -> 0 | U36: {=IF(BA36>0,0,SUMPRODUCT((BA$25:BA$124=0)*($B$25:$B$124>=$B36)*($B$25:$B$124<=$B36+ANALYSIS!$G$5)*($C$25:$C$124>=$C36)*($C$25:$C$124<=$C36+ANALYSIS!$G$6)))} -> 0 | V36: {=IF(BB36>0,0,SUMPRODUCT((BB$25:BB$124=0)*($B$25:$B$124>=$B36)*($B$25:$B$124<=$B36+ANALYSIS!$G$5)*($C$25:$C$124>=$C36)*($C$25:$C$124<=$C36+ANALYSIS!$G$6)))} -> 0 | W36: {=IF(BC36>0,0,SUMPRODUCT((BC$25:BC$124=0)*($B$25:$B$124>=$B36)*($B$25:$B$124<=$B36+ANALYSIS!$G$5)*($C$25:$C$124>=$C36)*($C$25:$C$124<=$C36+ANALYSIS!$G$6)))} -> 0 | X36: {=IF(BD36>0,0,SUMPRODUCT((BD$25:BD$124=0)*($B$25:$B$124>=$B36)*($B$25:$B$124<=$B36+ANALYSIS!$G$5)*($C$25:$C$124>=$C36)*($C$25:$C$124<=$C36+ANALYSIS!$G$6)))} -> 0 | Y36: {=IF(BE36>0,0,SUMPRODUCT((BE$25:BE$124=0)*($B$25:$B$124>=$B36)*($B$25:$B$124<=$B36+ANALYSIS!$G$5)*($C$25:$C$124>=$C36)*($C$25:$C$124<=$C36+ANALYSIS!$G$6)))} -> 0 | ... AF36: {=IF(BL36>0,0,SUMPRODUCT((BL$25:BL$124=0)*($B$25:$B$124>=$B36)*($B$25:$B$124<=$B36+ANALYSIS!$G$5)*($C$25:$C$124>=$C36)*($C$25:$C$124<=$C36+ANALYSIS!$G$6)))} -> 0 | AH36: =IF(AND(AX36=0,$B36>=R$22,$B36<=R$22+ANALYSIS!$G$5,$C36>=R$23,$C36<=R$23+ANALYSIS!$G$6),1,0) -> 1 | AI36: =IF(AND(AY36=0,$B36>=S$22,$B36<=S$22+ANALYSIS!$G$5,$C36>=S$23,$C36<=S$23+ANALYSIS!$G$6),1,0) -> 0 | AJ36: =IF(AND(AZ36=0,$B36>=T$22,$B36<=T$22+ANALYSIS!$G$5,$C36>=T$23,$C36<=T$23+ANALYSIS!$G$6),1,0) -> 0 | AK36: =IF(AND(BA36=0,$B36>=U$22,$B36<=U$22+ANALYSIS!$G$5,$C36>=U$23,$C36<=U$23+ANALYSIS!$G$6),1,0) -> 0 | AL36: =IF(AND(BB36=0,$B36>=V$22,$B36<=V$22+ANALYSIS!$G$5,$C36>=V$23,$C36<=V$23+ANALYSIS!$G$6),1,0) -> 0 | AM36: =IF(AND(BC36=0,$B36>=W$22,$B36<=W$22+ANALYSIS!$G$5,$C36>=W$23,$C36<=W$23+ANALYSIS!$G$6),1,0) -> 0 | AN36: =IF(AND(BD36=0,$B36>=X$22,$B36<=X$22+ANALYSIS!$G$5,$C36>=X$23,$C36<=X$23+ANALYSIS!$G$6),1,0) -> 0 | AO36: =IF(AND(BE36=0,$B36>=Y$22,$B36<=Y$22+ANALYSIS!$G$5,$C36>=Y$23,$C36<=Y$23+ANALYSIS!$G$6),1,0) -> 0 | ... AV36: =IF(AND(BL36=0,$B36>=AF$22,$B36<=AF$22+ANALYSIS!$G$5,$C36>=AF$23,$C36<=AF$23+ANALYSIS!$G$6),1,0) -> 0 | AX36: 0 | AY36: =AX36+AH36 -> 1 | AZ36: =AY36+AI36 -> 1 | BA36: =AZ36+AJ36 -> 1 | BB36: =BA36+AK36 -> 1 | BC36: =BB36+AL36 -> 1 | BD36: =BC36+AM36 -> 1 | BE36: =BD36+AN36 -> 1 | BF36: =BE36+AO36 -> 1 | ... BM36: =BL36+AV36 -> 1
... A124: =ANALYSIS!B130 -> 20-50 | B124: =ANALYSIS!E130 -> 57 | C124: =ANALYSIS!G130 -> 24.41 | D124: =IFERROR(MATCH(1,$AH124:$AV124,0),"") -> 12 | R124: {=IF(AX124>0,0,SUMPRODUCT((AX$25:AX$124=0)*($B$25:$B$124>=$B124)*($B$25:$B$124<=$B124+ANALYSIS!$G$5)*($C$25:$C$124>=$C124)*($C$25:$C$124<=$C124+ANALYSIS!$G$6)))} -> 4 | S124: {=IF(AY124>0,0,SUMPRODUCT((AY$25:AY$124=0)*($B$25:$B$124>=$B124)*($B$25:$B$124<=$B124+ANALYSIS!$G$5)*($C$25:$C$124>=$C124)*($C$25:$C$124<=$C124+ANALYSIS!$G$6)))} -> 4 | T124: {=IF(AZ124>0,0,SUMPRODUCT((AZ$25:AZ$124=0)*($B$25:$B$124>=$B124)*($B$25:$B$124<=$B124+ANALYSIS!$G$5)*($C$25:$C$124>=$C124)*($C$25:$C$124<=$C124+ANALYSIS!$G$6)))} -> 4 | U124: {=IF(BA124>0,0,SUMPRODUCT((BA$25:BA$124=0)*($B$25:$B$124>=$B124)*($B$25:$B$124<=$B124+ANALYSIS!$G$5)*($C$25:$C$124>=$C124)*($C$25:$C$124<=$C124+ANALYSIS!$G$6)))} -> 4 | V124: {=IF(BB124>0,0,SUMPRODUCT((BB$25:BB$124=0)*($B$25:$B$124>=$B124)*($B$25:$B$124<=$B124+ANALYSIS!$G$5)*($C$25:$C$124>=$C124)*($C$25:$C$124<=$C124+ANALYSIS!$G$6)))} -> 4 | W124: {=IF(BC124>0,0,SUMPRODUCT((BC$25:BC$124=0)*($B$25:$B$124>=$B124)*($B$25:$B$124<=$B124+ANALYSIS!$G$5)*($C$25:$C$124>=$C124)*($C$25:$C$124<=$C124+ANALYSIS!$G$6)))} -> 4 | X124: {=IF(BD124>0,0,SUMPRODUCT((BD$25:BD$124=0)*($B$25:$B$124>=$B124)*($B$25:$B$124<=$B124+ANALYSIS!$G$5)*($C$25:$C$124>=$C124)*($C$25:$C$124<=$C124+ANALYSIS!$G$6)))} -> 4 | Y124: {=IF(BE124>0,0,SUMPRODUCT((BE$25:BE$124=0)*($B$25:$B$124>=$B124)*($B$25:$B$124<=$B124+ANALYSIS!$G$5)*($C$25:$C$124>=$C124)*($C$25:$C$124<=$C124+ANALYSIS!$G$6)))} -> 4 | ... AF124: {=IF(BL124>0,0,SUMPRODUCT((BL$25:BL$124=0)*($B$25:$B$124>=$B124)*($B$25:$B$124<=$B124+ANALYSIS!$G$5)*($C$25:$C$124>=$C124)*($C$25:$C$124<=$C124+ANALYSIS!$G$6)))} -> 0 | AH124: =IF(AND(AX124=0,$B124>=R$22,$B124<=R$22+ANALYSIS!$G$5,$C124>=R$23,$C124<=R$23+ANALYSIS!$G$6),1,0) -> 0 | AI124: =IF(AND(AY124=0,$B124>=S$22,$B124<=S$22+ANALYSIS!$G$5,$C124>=S$23,$C124<=S$23+ANALYSIS!$G$6),1,0) -> 0 | AJ124: =IF(AND(AZ124=0,$B124>=T$22,$B124<=T$22+ANALYSIS!$G$5,$C124>=T$23,$C124<=T$23+ANALYSIS!$G$6),1,0) -> 0 | AK124: =IF(AND(BA124=0,$B124>=U$22,$B124<=U$22+ANALYSIS!$G$5,$C124>=U$23,$C124<=U$23+ANALYSIS!$G$6),1,0) -> 0 | AL124: =IF(AND(BB124=0,$B124>=V$22,$B124<=V$22+ANALYSIS!$G$5,$C124>=V$23,$C124<=V$23+ANALYSIS!$G$6),1,0) -> 0 | AM124: =IF(AND(BC124=0,$B124>=W$22,$B124<=W$22+ANALYSIS!$G$5,$C124>=W$23,$C124<=W$23+ANALYSIS!$G$6),1,0) -> 0 | AN124: =IF(AND(BD124=0,$B124>=X$22,$B124<=X$22+ANALYSIS!$G$5,$C124>=X$23,$C124<=X$23+ANALYSIS!$G$6),1,0) -> 0 | AO124: =IF(AND(BE124=0,$B124>=Y$22,$B124<=Y$22+ANALYSIS!$G$5,$C124>=Y$23,$C124<=Y$23+ANALYSIS!$G$6),1,0) -> 0 | ... AV124: =IF(AND(BL124=0,$B124>=AF$22,$B124<=AF$22+ANALYSIS!$G$5,$C124>=AF$23,$C124<=AF$23+ANALYSIS!$G$6),1,0) -> 0 | AX124: 0 | AY124: =AX124+AH124 -> 0 | AZ124: =AY124+AI124 -> 0 | BA124: =AZ124+AJ124 -> 0 | BB124: =BA124+AK124 -> 0 | BC124: =BB124+AL124 -> 0 | BD124: =BC124+AM124 -> 0 | BE124: =BD124+AN124 -> 0 | BF124: =BE124+AO124 -> 0 | ... BM124: =BL124+AV124 -> 1

Sheet GROUPS
A1: ="Arrow Groups — within "&$B$6&" lb spine and "&$B$7&" g weight" -> Arrow Groups — within 3 lb spine and 0.5 g weight
A2: ="Method: each shaft is placed in a spine band "&$B$6&" lb wide and a weight band "&$B$7&" g wide. Every shaft sharing a band pair is therefore within "&$B$6&" lb of spine and "&$B$7&" g of weight of every other member. Group size is unrestricted." -> Method: each shaft is placed in a spine band 3 lb wide and a weight band 0.5 g wide. Every shaft sharing a band pair is therefore within 3 lb of spine and 0.5 g of weight of every other member. Group size is unrestricted.
A3: Caveat: fixed band edges can split two near-identical shafts (e.g. 22.98 g vs 23.02 g). Shift the band edges by changing the tolerances on ANALYSIS, or check neighbouring rows in the matrix below.
A5: Tolerances (set on ANALYSIS)
A6: Max spine spread (lb) | B6: =ANALYSIS!$G$5 -> 3
A7: Max weight spread (g) | B7: =ANALYSIS!$G$6 -> 0.5
A8: Min shafts to count as usable | B8: =ANALYSIS!$G$7 -> 3
A9: Distinct groups found | B9: =COUNTA(B15:B80) -> 29 | C9: Largest group (shafts) | D9: =MAX(E15:E80) -> 10
A10: Usable groups (≥ min size) | B10: =COUNTIF(M15:M80,"Yes") -> 15 | C10: Usable groups fully in 55–60 lb | D10: =COUNTIFS(M15:M80,"Yes",L15:L80,"Yes") -> 12
A11: Shafts inside usable groups | B11: =SUMIF(M15:M80,"Yes",E15:E80) -> 79 | C11: Shafts in usable, in-spec groups | D11: =SUMIFS(E15:E80,M15:M80,"Yes",L15:L80,"Yes") -> 64
A13: Group list (sorted largest first)
A14: ID | B14: Group key | C14: Spine band (lb) | D14: Wt band (g) | E14: Shafts | F14: Min spine | G14: Max spine | H14: Spine spread | I14: Min wt (g) | J14: Max wt (g) | K14: Wt spread (g) | L14: All in 55–60? | M14: Usable? | N14: Member shafts
A15: =IF($B15="","",ROW()-14) -> 1 | B15: {=_xlfn.SORTBY(_xlfn.UNIQUE(ANALYSIS!$O$31:$O$130),COUNTIF(ANALYSIS!$O$31:$O$130,_xlfn.UNIQUE(ANALYSIS!$O$31:$O$130)),-1,_xlfn.UNIQUE(ANALYSIS!$O$31:$O$130),1)} -> 54.0 lb / 23.5 g | C15: =IF($B15="","",_xlfn.MINIFS(ANALYSIS!$M$31:$M$130,ANALYSIS!$O$31:$O$130,$B15)) -> 54 | D15: =IF($B15="","",_xlfn.MINIFS(ANALYSIS!$N$31:$N$130,ANALYSIS!$O$31:$O$130,$B15)) -> 23.5 | E15: =IF($B15="","",COUNTIF(ANALYSIS!$O$31:$O$130,$B15)) -> 10 | F15: =IF($B15="","",_xlfn.MINIFS(ANALYSIS!$E$31:$E$130,ANALYSIS!$O$31:$O$130,$B15)) -> 55 | G15: =IF($B15="","",_xlfn.MAXIFS(ANALYSIS!$E$31:$E$130,ANALYSIS!$O$31:$O$130,$B15)) -> 56 | H15: =IF($B15="","",G15-F15) -> 1 | I15: =IF($B15="","",_xlfn.MINIFS(ANALYSIS!$G$31:$G$130,ANALYSIS!$O$31:$O$130,$B15)) -> 23.71 | J15: =IF($B15="","",_xlfn.MAXIFS(ANALYSIS!$G$31:$G$130,ANALYSIS!$O$31:$O$130,$B15)) -> 23.97 | K15: =IF($B15="","",J15-I15) -> 0.26 | L15: =IF($B15="","",IF(AND(F15>=ANALYSIS!$B$5,G15<=ANALYSIS!$B$6),"Yes","No")) -> Yes | M15: =IF($B15="","",IF(E15>=$B$8,"Yes","No")) -> Yes | N15: {=IF($B15="","",_xlfn.TEXTJOIN(", ",TRUE,IF(ANALYSIS!$O$31:$O$130=$B15,ANALYSIS!$B$31:$B$130,"")))} -> 19-06, 19-45, 20-03, 20-16, 20-21, 20-23, 20-33, 20-35, 20-44, 20-45
